2023-04-18 19:52:01,020 - utils.database - INFO -> Sending new connection
2023-04-18 19:52:01,020 - __main__ - INFO -> Reading Data file
2023-04-18 19:52:01,041 - __main__ - INFO -> Finished
2023-04-18 19:54:43,123 - utils.database - INFO -> Sending new connection
2023-04-18 19:54:43,123 - __main__ - INFO -> Reading Data file
2023-04-18 19:54:43,130 - __main__ - INFO -> Index(['OrderNumber', 'ClientName', 'ProductName', 'ProductType', 'UnitPrice',
       'ProductQuantity', 'TotalPrice', 'Currency', 'DeliveryAddress',
       'DeliveryCity', 'DeliveryPostcode', 'DeliveryCountry',
       'DeliveryContactNumber', 'PaymentType', 'PaymentBillingCode',
       'PaymentDate'],
      dtype='object')
2023-04-18 19:54:43,132 - __main__ - INFO ->    OrderNumber    ClientName
0  PO0060504-1  MacGyver Inc
1  PO0060504-2    Howell LLC
2  PO0060504-3    HOWELL LLC
3  PO0060504-4    HOWELL LLC
4  PO0060504-5    Howell LLC
2023-04-18 19:54:43,143 - __main__ - INFO -> Finished
2023-04-18 19:54:49,174 - utils.database - INFO -> Sending new connection
2023-04-18 19:54:49,175 - __main__ - INFO -> Reading Data file
2023-04-18 19:54:49,180 - __main__ - INFO -> Index(['OrderNumber', 'ClientName', 'ProductName', 'ProductType', 'UnitPrice',
       'ProductQuantity', 'TotalPrice', 'Currency', 'DeliveryAddress',
       'DeliveryCity', 'DeliveryPostcode', 'DeliveryCountry',
       'DeliveryContactNumber', 'PaymentType', 'PaymentBillingCode',
       'PaymentDate'],
      dtype='object')
2023-04-18 19:54:49,182 - __main__ - INFO ->    OrderNumber    ClientName
0  PO0060504-1  MacGyver Inc
1  PO0060504-2    Howell LLC
2  PO0060504-3    HOWELL LLC
3  PO0060504-4    HOWELL LLC
4  PO0060504-5    Howell LLC
2023-04-18 19:54:49,196 - __main__ - INFO -> Finished
2023-04-18 19:57:51,125 - utils.database - INFO -> Sending new connection
2023-04-18 19:57:51,126 - __main__ - INFO -> Reading Data file
2023-04-18 19:57:51,126 - __main__ - INFO -> Reading Data file
2023-04-18 19:57:51,130 - __main__ - INFO -> Index(['OrderNumber', 'ClientName', 'ProductName', 'ProductType', 'UnitPrice',
       'ProductQuantity', 'TotalPrice', 'Currency', 'DeliveryAddress',
       'DeliveryCity', 'DeliveryPostcode', 'DeliveryCountry',
       'DeliveryContactNumber', 'PaymentType', 'PaymentBillingCode',
       'PaymentDate'],
      dtype='object')
2023-04-18 19:57:51,132 - __main__ - INFO ->    OrderNumber    ClientName
0  PO0060504-1  MacGyver Inc
1  PO0060504-2    Howell LLC
2  PO0060504-3    HOWELL LLC
3  PO0060504-4    HOWELL LLC
4  PO0060504-5    Howell LLC
2023-04-18 19:57:51,143 - __main__ - INFO -> Finished
2023-04-18 19:58:29,568 - utils.database - INFO -> Sending new connection
2023-04-18 19:58:29,568 - __main__ - INFO -> Reading Data file
2023-04-18 19:58:29,570 - __main__ - ERROR -> File not found
Traceback (most recent call last):
  File "d:\project\main.py", line 11, in read_data
    df = pd.read_csv(file_path)
         ^^^^^^^^^^^^^^^^^^^^^^
  File "C:\Users\Administrator\AppData\Local\Programs\Python\Python311\Lib\site-packages\pandas\io\parsers\readers.py", line 912, in read_csv
    return _read(filepath_or_buffer, kwds)
           ^^^^^^^^^^^^^^^^^^^^^^^^^^^^^^^
  File "C:\Users\Administrator\AppData\Local\Programs\Python\Python311\Lib\site-packages\pandas\io\parsers\readers.py", line 577, in _read
    parser = TextFileReader(filepath_or_buffer, **kwds)
             ^^^^^^^^^^^^^^^^^^^^^^^^^^^^^^^^^^^^^^^^^^
  File "C:\Users\Administrator\AppData\Local\Programs\Python\Python311\Lib\site-packages\pandas\io\parsers\readers.py", line 1407, in __init__
    self._engine = self._make_engine(f, self.engine)
                   ^^^^^^^^^^^^^^^^^^^^^^^^^^^^^^^^^
  File "C:\Users\Administrator\AppData\Local\Programs\Python\Python311\Lib\site-packages\pandas\io\parsers\readers.py", line 1661, in _make_engine
    self.handles = get_handle(
                   ^^^^^^^^^^^
  File "C:\Users\Administrator\AppData\Local\Programs\Python\Python311\Lib\site-packages\pandas\io\common.py", line 859, in get_handle
    handle = open(
             ^^^^^
FileNotFoundError: [Errno 2] No such file or directory: 'data/input/data.csv'
2023-04-18 20:00:16,731 - utils.database - INFO -> Sending new connection
2023-04-18 20:00:16,732 - __main__ - INFO -> Reading Data file
2023-04-18 20:00:16,733 - __main__ - ERROR -> File not found
Traceback (most recent call last):
  File "d:\project\main.py", line 11, in read_data
    df = pd.read_csv(file_path)
         ^^^^^^^^^^^^^^^^^^^^^^
  File "C:\Users\Administrator\AppData\Local\Programs\Python\Python311\Lib\site-packages\pandas\io\parsers\readers.py", line 912, in read_csv
    return _read(filepath_or_buffer, kwds)
           ^^^^^^^^^^^^^^^^^^^^^^^^^^^^^^^
  File "C:\Users\Administrator\AppData\Local\Programs\Python\Python311\Lib\site-packages\pandas\io\parsers\readers.py", line 577, in _read
    parser = TextFileReader(filepath_or_buffer, **kwds)
             ^^^^^^^^^^^^^^^^^^^^^^^^^^^^^^^^^^^^^^^^^^
  File "C:\Users\Administrator\AppData\Local\Programs\Python\Python311\Lib\site-packages\pandas\io\parsers\readers.py", line 1407, in __init__
    self._engine = self._make_engine(f, self.engine)
                   ^^^^^^^^^^^^^^^^^^^^^^^^^^^^^^^^^
  File "C:\Users\Administrator\AppData\Local\Programs\Python\Python311\Lib\site-packages\pandas\io\parsers\readers.py", line 1661, in _make_engine
    self.handles = get_handle(
                   ^^^^^^^^^^^
  File "C:\Users\Administrator\AppData\Local\Programs\Python\Python311\Lib\site-packages\pandas\io\common.py", line 859, in get_handle
    handle = open(
             ^^^^^
FileNotFoundError: [Errno 2] No such file or directory: 'data/input/data.csv'
2023-04-18 20:00:16,738 - __main__ - INFO -> Finished
2023-04-18 20:00:59,657 - utils.database - INFO -> Sending new connection
2023-04-18 20:00:59,657 - __main__ - INFO -> Reading Data file
2023-04-18 20:00:59,658 - __main__ - ERROR -> File not found
2023-04-18 20:00:59,658 - __main__ - INFO -> Finished
2023-04-18 20:03:42,988 - utils.database - INFO -> Sending new connection
2023-04-18 20:03:42,988 - __main__ - INFO -> Reading Data file
2023-04-18 20:03:42,990 - __main__ - ERROR -> File not found
2023-04-18 20:03:55,128 - utils.database - INFO -> Sending new connection
2023-04-18 20:03:55,128 - __main__ - INFO -> Reading Data file
2023-04-18 20:03:55,130 - __main__ - ERROR -> File not found
2023-04-18 20:03:55,130 - __main__ - ERROR -> LALALA
Traceback (most recent call last):
  File "d:\project\main.py", line 11, in read_data
    df = pd.read_csv(file_path)
         ^^^^^^^^^^^^^^^^^^^^^^
  File "C:\Users\Administrator\AppData\Local\Programs\Python\Python311\Lib\site-packages\pandas\io\parsers\readers.py", line 912, in read_csv
    return _read(filepath_or_buffer, kwds)
           ^^^^^^^^^^^^^^^^^^^^^^^^^^^^^^^
  File "C:\Users\Administrator\AppData\Local\Programs\Python\Python311\Lib\site-packages\pandas\io\parsers\readers.py", line 577, in _read
    parser = TextFileReader(filepath_or_buffer, **kwds)
             ^^^^^^^^^^^^^^^^^^^^^^^^^^^^^^^^^^^^^^^^^^
  File "C:\Users\Administrator\AppData\Local\Programs\Python\Python311\Lib\site-packages\pandas\io\parsers\readers.py", line 1407, in __init__
    self._engine = self._make_engine(f, self.engine)
                   ^^^^^^^^^^^^^^^^^^^^^^^^^^^^^^^^^
  File "C:\Users\Administrator\AppData\Local\Programs\Python\Python311\Lib\site-packages\pandas\io\parsers\readers.py", line 1661, in _make_engine
    self.handles = get_handle(
                   ^^^^^^^^^^^
  File "C:\Users\Administrator\AppData\Local\Programs\Python\Python311\Lib\site-packages\pandas\io\common.py", line 859, in get_handle
    handle = open(
             ^^^^^
FileNotFoundError: [Errno 2] No such file or directory: 'data/input/data.csv'
2023-04-18 20:03:55,154 - __main__ - INFO -> Finished
2023-04-18 20:04:52,275 - utils.database - INFO -> Sending new connection
2023-04-18 20:04:52,275 - __main__ - INFO -> Reading Data file
2023-04-18 20:04:52,279 - __main__ - ERROR -> data/input/data.csv does not exists!
Traceback (most recent call last):
  File "d:\project\main.py", line 11, in read_data
    df = pd.read_csv(file_path)
         ^^^^^^^^^^^^^^^^^^^^^^
  File "C:\Users\Administrator\AppData\Local\Programs\Python\Python311\Lib\site-packages\pandas\io\parsers\readers.py", line 912, in read_csv
    return _read(filepath_or_buffer, kwds)
           ^^^^^^^^^^^^^^^^^^^^^^^^^^^^^^^
  File "C:\Users\Administrator\AppData\Local\Programs\Python\Python311\Lib\site-packages\pandas\io\parsers\readers.py", line 577, in _read
    parser = TextFileReader(filepath_or_buffer, **kwds)
             ^^^^^^^^^^^^^^^^^^^^^^^^^^^^^^^^^^^^^^^^^^
  File "C:\Users\Administrator\AppData\Local\Programs\Python\Python311\Lib\site-packages\pandas\io\parsers\readers.py", line 1407, in __init__
    self._engine = self._make_engine(f, self.engine)
                   ^^^^^^^^^^^^^^^^^^^^^^^^^^^^^^^^^
  File "C:\Users\Administrator\AppData\Local\Programs\Python\Python311\Lib\site-packages\pandas\io\parsers\readers.py", line 1661, in _make_engine
    self.handles = get_handle(
                   ^^^^^^^^^^^
  File "C:\Users\Administrator\AppData\Local\Programs\Python\Python311\Lib\site-packages\pandas\io\common.py", line 859, in get_handle
    handle = open(
             ^^^^^
FileNotFoundError: [Errno 2] No such file or directory: 'data/input/data.csv'
2023-04-18 20:04:52,284 - __main__ - INFO -> Finished
2023-04-18 20:59:56,022 - utils.database - INFO -> Sending new connection
2023-04-18 20:59:56,028 - __main__ - INFO -> Reading Data file
2023-04-18 20:59:56,036 - __main__ - INFO -> Reading Data file
2023-04-18 21:04:23,474 - utils.database - INFO -> Sending new connection
2023-04-18 21:04:23,474 - __main__ - INFO -> Reading Data file
2023-04-18 21:04:23,490 - __main__ - INFO -> Reading Data file
2023-04-18 21:04:23,490 - utils.database - INFO -> SELECT n, a, m, e FROM sqlite_master WHERE type='table' AND name=client_dim
2023-04-18 21:05:10,360 - utils.database - INFO -> Sending new connection
2023-04-18 21:05:10,360 - __main__ - INFO -> Reading Data file
2023-04-18 21:05:10,368 - __main__ - INFO -> Reading Data file
2023-04-18 21:05:10,369 - utils.database - INFO -> SELECT name FROM sqlite_master WHERE type='table' AND name=client_dim
2023-04-18 21:06:08,013 - utils.database - INFO -> Sending new connection
2023-04-18 21:06:08,013 - __main__ - INFO -> Reading Data file
2023-04-18 21:06:08,020 - __main__ - INFO -> Reading Data file
2023-04-18 21:06:08,021 - utils.database - INFO -> SELECT name FROM sqlite_master WHERE type='table' AND name='client_dim'
2023-04-18 21:37:33,403 - utils.database - INFO -> Sending new connection
2023-04-18 21:37:33,404 - __main__ - INFO -> Reading Data file
2023-04-18 21:37:33,408 - __main__ - INFO -> Reading Data file
2023-04-18 21:41:28,340 - utils.database - INFO -> Sending new connection
2023-04-18 21:41:28,341 - __main__ - INFO -> Reading Data file
2023-04-18 21:41:28,346 - __main__ - INFO -> Reading Data file
2023-04-18 21:41:28,351 - utils.database - INFO -> SELECT name FROM sqlite_master WHERE type='table' AND name='orders_fact'
2023-04-18 21:41:28,380 - __main__ - ERROR -> Failed to ingest data in Orders table!
Traceback (most recent call last):
  File "d:\project\main.py", line 54, in order_ingestion
    required_df.to_sql(name='orders_fact', con=conn, if_exists='append', index=False)
  File "C:\Users\Administrator\AppData\Local\Programs\Python\Python311\Lib\site-packages\pandas\core\generic.py", line 2987, in to_sql
    return sql.to_sql(
           ^^^^^^^^^^^
  File "C:\Users\Administrator\AppData\Local\Programs\Python\Python311\Lib\site-packages\pandas\io\sql.py", line 695, in to_sql
    return pandas_sql.to_sql(
           ^^^^^^^^^^^^^^^^^^
  File "C:\Users\Administrator\AppData\Local\Programs\Python\Python311\Lib\site-packages\pandas\io\sql.py", line 2187, in to_sql
    table.create()
  File "C:\Users\Administrator\AppData\Local\Programs\Python\Python311\Lib\site-packages\pandas\io\sql.py", line 827, in create
    if self.exists():
       ^^^^^^^^^^^^^
  File "C:\Users\Administrator\AppData\Local\Programs\Python\Python311\Lib\site-packages\pandas\io\sql.py", line 814, in exists
    return self.pd_sql.has_table(self.name, self.schema)
           ^^^^^^^^^^^^^^^^^^^^^^^^^^^^^^^^^^^^^^^^^^^^^
  File "C:\Users\Administrator\AppData\Local\Programs\Python\Python311\Lib\site-packages\pandas\io\sql.py", line 2195, in has_table
    return len(self.execute(query, [name]).fetchall()) > 0
               ^^^^^^^^^^^^^^^^^^^^^^^^^^^
  File "C:\Users\Administrator\AppData\Local\Programs\Python\Python311\Lib\site-packages\pandas\io\sql.py", line 2016, in execute
    cur = self.con.cursor()
          ^^^^^^^^^^^^^^^^^
sqlite3.ProgrammingError: Cannot operate on a closed database.
2023-04-18 21:42:28,629 - utils.database - INFO -> Sending new connection
2023-04-18 21:42:28,629 - __main__ - INFO -> Reading Data file
2023-04-18 21:42:28,634 - __main__ - INFO -> Reading Data file
2023-04-18 21:42:28,639 - utils.database - INFO -> SELECT name FROM sqlite_master WHERE type='table' AND name='orders_fact'
2023-04-18 21:42:28,642 - __main__ - ERROR -> Failed to ingest data in Orders table!
Traceback (most recent call last):
  File "d:\project\main.py", line 54, in order_ingestion
    required_df.to_sql(name='orders_fact', con=conn, if_exists='append', index=False)
  File "C:\Users\Administrator\AppData\Local\Programs\Python\Python311\Lib\site-packages\pandas\core\generic.py", line 2987, in to_sql
    return sql.to_sql(
           ^^^^^^^^^^^
  File "C:\Users\Administrator\AppData\Local\Programs\Python\Python311\Lib\site-packages\pandas\io\sql.py", line 695, in to_sql
    return pandas_sql.to_sql(
           ^^^^^^^^^^^^^^^^^^
  File "C:\Users\Administrator\AppData\Local\Programs\Python\Python311\Lib\site-packages\pandas\io\sql.py", line 2187, in to_sql
    table.create()
  File "C:\Users\Administrator\AppData\Local\Programs\Python\Python311\Lib\site-packages\pandas\io\sql.py", line 838, in create
    self._execute_create()
  File "C:\Users\Administrator\AppData\Local\Programs\Python\Python311\Lib\site-packages\pandas\io\sql.py", line 1871, in _execute_create
    conn.execute(stmt)
sqlite3.OperationalError: table "orders_fact" already exists
2023-04-19 13:49:09,174 - utils.database - INFO -> Sending new connection
2023-04-19 13:49:09,181 - __main__ - INFO -> Reading Data file
2023-04-19 13:49:09,199 - __main__ - INFO -> Reading Data file
2023-04-19 13:49:09,199 - __main__ - INFO -> OrderNumber              object
ClientName               object
ProductName              object
ProductType              object
UnitPrice                 int64
ProductQuantity           int64
TotalPrice                int64
Currency                 object
DeliveryAddress          object
DeliveryCity             object
DeliveryPostcode         object
DeliveryCountry          object
DeliveryContactNumber    object
PaymentType              object
PaymentBillingCode       object
PaymentDate              object
dtype: object
2023-04-19 13:49:09,227 - utils.database - INFO -> SELECT name FROM sqlite_master WHERE type='table' AND name='orders_fact'
2023-04-19 13:49:09,243 - __main__ - ERROR -> Failed to ingest data in Orders table!
Traceback (most recent call last):
  File "d:\project\main.py", line 59, in order_ingestion
    required_df.to_sql(name='orders_fact', con=conn, if_exists='append', index=False)
  File "C:\Users\Administrator\AppData\Local\Programs\Python\Python311\Lib\site-packages\pandas\core\generic.py", line 2987, in to_sql
    return sql.to_sql(
           ^^^^^^^^^^^
  File "C:\Users\Administrator\AppData\Local\Programs\Python\Python311\Lib\site-packages\pandas\io\sql.py", line 695, in to_sql
    return pandas_sql.to_sql(
           ^^^^^^^^^^^^^^^^^^
  File "C:\Users\Administrator\AppData\Local\Programs\Python\Python311\Lib\site-packages\pandas\io\sql.py", line 2187, in to_sql
    table.create()
  File "C:\Users\Administrator\AppData\Local\Programs\Python\Python311\Lib\site-packages\pandas\io\sql.py", line 838, in create
    self._execute_create()
  File "C:\Users\Administrator\AppData\Local\Programs\Python\Python311\Lib\site-packages\pandas\io\sql.py", line 1871, in _execute_create
    conn.execute(stmt)
sqlite3.OperationalError: table "orders_fact" already exists
2023-04-19 13:51:35,220 - utils.database - INFO -> Sending new connection
2023-04-19 13:51:35,220 - __main__ - INFO -> Reading Data file
2023-04-19 13:51:35,228 - __main__ - INFO -> Reading Data file
2023-04-19 13:51:35,228 - __main__ - INFO -> OrderNumber              object
ClientName               object
ProductName              object
ProductType              object
UnitPrice                 int64
ProductQuantity           int64
TotalPrice                int64
Currency                 object
DeliveryAddress          object
DeliveryCity             object
DeliveryPostcode         object
DeliveryCountry          object
DeliveryContactNumber    object
PaymentType              object
PaymentBillingCode       object
PaymentDate              object
dtype: object
2023-04-19 13:51:35,236 - __main__ - INFO -> ---
2023-04-19 13:51:35,236 - __main__ - INFO -> OrderNumber               object
ClientName                object
ProductName               object
ProductType               object
UnitPrice                float64
ProductQuantity            int64
TotalPrice                 int64
Currency                  object
DeliveryAddress           object
DeliveryCity              object
DeliveryPostcode          object
DeliveryCountry           object
DeliveryContactNumber     object
PaymentType               object
PaymentBillingCode        object
PaymentDate               object
dtype: object
2023-04-19 13:51:35,276 - utils.database - INFO -> SELECT name FROM sqlite_master WHERE type='table' AND name='orders_fact'
2023-04-19 13:51:35,284 - __main__ - ERROR -> Failed to ingest data in Orders table!
Traceback (most recent call last):
  File "d:\project\main.py", line 62, in order_ingestion
    required_df.to_sql(name='orders_fact', con=conn, if_exists='append', index=False)
  File "C:\Users\Administrator\AppData\Local\Programs\Python\Python311\Lib\site-packages\pandas\core\generic.py", line 2987, in to_sql
    return sql.to_sql(
           ^^^^^^^^^^^
  File "C:\Users\Administrator\AppData\Local\Programs\Python\Python311\Lib\site-packages\pandas\io\sql.py", line 695, in to_sql
    return pandas_sql.to_sql(
           ^^^^^^^^^^^^^^^^^^
  File "C:\Users\Administrator\AppData\Local\Programs\Python\Python311\Lib\site-packages\pandas\io\sql.py", line 2187, in to_sql
    table.create()
  File "C:\Users\Administrator\AppData\Local\Programs\Python\Python311\Lib\site-packages\pandas\io\sql.py", line 838, in create
    self._execute_create()
  File "C:\Users\Administrator\AppData\Local\Programs\Python\Python311\Lib\site-packages\pandas\io\sql.py", line 1871, in _execute_create
    conn.execute(stmt)
sqlite3.OperationalError: table "orders_fact" already exists
2023-04-19 13:51:59,629 - utils.database - INFO -> Sending new connection
2023-04-19 13:51:59,629 - __main__ - INFO -> Reading Data file
2023-04-19 13:51:59,637 - __main__ - INFO -> Reading Data file
2023-04-19 13:51:59,637 - __main__ - INFO -> OrderNumber              object
ClientName               object
ProductName              object
ProductType              object
UnitPrice                 int64
ProductQuantity           int64
TotalPrice                int64
Currency                 object
DeliveryAddress          object
DeliveryCity             object
DeliveryPostcode         object
DeliveryCountry          object
DeliveryContactNumber    object
PaymentType              object
PaymentBillingCode       object
PaymentDate              object
dtype: object
2023-04-19 13:51:59,645 - __main__ - INFO -> ---
2023-04-19 13:51:59,645 - __main__ - INFO ->    OrderNumber    ClientName   ProductName ProductType  UnitPrice  ...  DeliveryCountry  DeliveryContactNumber PaymentType  PaymentBillingCode PaymentDate
0  PO0060504-1  MacGyver Inc         Piano    Keyboard     4700.0  ...   United Kingdom        +44 7911 843910       Debit  PO0060504-20210321   3/21/2021
1  PO0060504-2    Howell LLC  Bamboo Flute    Woodwind       60.0  ...   UNITED KINGDOM       +44 151 496 0566      Credit  PO0087294-20210317   3/17/2021
2  PO0060504-3    HOWELL LLC          Harp      String      940.0  ...   UNITED KINGDOM       +44 151 496 0566      Credit  PO0087294-20210317   3/17/2021
3  PO0060504-4    HOWELL LLC         Piano    Keyboard     4700.0  ...   UNITED KINGDOM       +44 151 496 0566      Credit  PO0087294-20210317   3/17/2021
4  PO0060504-5    Howell LLC    Snare Drum  Percussion      350.0  ...   UNITED KINGDOM       +44 151 496 0566      Credit  PO0087294-20210317   3/17/2021

[5 rows x 16 columns]
2023-04-19 13:51:59,701 - __main__ - INFO -> OrderNumber               object
ClientName                object
ProductName               object
ProductType               object
UnitPrice                float64
ProductQuantity            int64
TotalPrice                 int64
Currency                  object
DeliveryAddress           object
DeliveryCity              object
DeliveryPostcode          object
DeliveryCountry           object
DeliveryContactNumber     object
PaymentType               object
PaymentBillingCode        object
PaymentDate               object
dtype: object
2023-04-19 13:51:59,717 - utils.database - INFO -> SELECT name FROM sqlite_master WHERE type='table' AND name='orders_fact'
2023-04-19 13:51:59,725 - __main__ - ERROR -> Failed to ingest data in Orders table!
Traceback (most recent call last):
  File "d:\project\main.py", line 63, in order_ingestion
    required_df.to_sql(name='orders_fact', con=conn, if_exists='append', index=False)
  File "C:\Users\Administrator\AppData\Local\Programs\Python\Python311\Lib\site-packages\pandas\core\generic.py", line 2987, in to_sql
    return sql.to_sql(
           ^^^^^^^^^^^
  File "C:\Users\Administrator\AppData\Local\Programs\Python\Python311\Lib\site-packages\pandas\io\sql.py", line 695, in to_sql
    return pandas_sql.to_sql(
           ^^^^^^^^^^^^^^^^^^
  File "C:\Users\Administrator\AppData\Local\Programs\Python\Python311\Lib\site-packages\pandas\io\sql.py", line 2187, in to_sql
    table.create()
  File "C:\Users\Administrator\AppData\Local\Programs\Python\Python311\Lib\site-packages\pandas\io\sql.py", line 838, in create
    self._execute_create()
  File "C:\Users\Administrator\AppData\Local\Programs\Python\Python311\Lib\site-packages\pandas\io\sql.py", line 1871, in _execute_create
    conn.execute(stmt)
sqlite3.OperationalError: table "orders_fact" already exists
2023-04-19 13:53:42,757 - utils.database - INFO -> Sending new connection
2023-04-19 13:53:42,757 - __main__ - INFO -> Reading Data file
2023-04-19 13:53:42,757 - __main__ - INFO -> Reading Data file
2023-04-19 13:53:42,757 - __main__ - INFO -> OrderNumber              object
ClientName               object
ProductName              object
ProductType              object
UnitPrice                 int64
ProductQuantity           int64
TotalPrice                int64
Currency                 object
DeliveryAddress          object
DeliveryCity             object
DeliveryPostcode         object
DeliveryCountry          object
DeliveryContactNumber    object
PaymentType              object
PaymentBillingCode       object
PaymentDate              object
dtype: object
2023-04-19 13:53:42,765 - __main__ - INFO -> ---
2023-04-19 13:53:42,765 - __main__ - INFO -> 0    4700.0
1      60.0
2     940.0
3    4700.0
4     350.0
Name: UnitPrice, dtype: float64
2023-04-19 13:53:42,773 - __main__ - INFO -> OrderNumber               object
ClientName                object
ProductName               object
ProductType               object
UnitPrice                float64
ProductQuantity            int64
TotalPrice                 int64
Currency                  object
DeliveryAddress           object
DeliveryCity              object
DeliveryPostcode          object
DeliveryCountry           object
DeliveryContactNumber     object
PaymentType               object
PaymentBillingCode        object
PaymentDate               object
dtype: object
2023-04-19 13:53:42,789 - utils.database - INFO -> SELECT name FROM sqlite_master WHERE type='table' AND name='orders_fact'
2023-04-19 13:53:42,789 - __main__ - ERROR -> Failed to ingest data in Orders table!
Traceback (most recent call last):
  File "d:\project\main.py", line 63, in order_ingestion
    required_df.to_sql(name='orders_fact', con=conn, if_exists='append', index=False)
  File "C:\Users\Administrator\AppData\Local\Programs\Python\Python311\Lib\site-packages\pandas\core\generic.py", line 2987, in to_sql
    return sql.to_sql(
           ^^^^^^^^^^^
  File "C:\Users\Administrator\AppData\Local\Programs\Python\Python311\Lib\site-packages\pandas\io\sql.py", line 695, in to_sql
    return pandas_sql.to_sql(
           ^^^^^^^^^^^^^^^^^^
  File "C:\Users\Administrator\AppData\Local\Programs\Python\Python311\Lib\site-packages\pandas\io\sql.py", line 2187, in to_sql
    table.create()
  File "C:\Users\Administrator\AppData\Local\Programs\Python\Python311\Lib\site-packages\pandas\io\sql.py", line 838, in create
    self._execute_create()
  File "C:\Users\Administrator\AppData\Local\Programs\Python\Python311\Lib\site-packages\pandas\io\sql.py", line 1871, in _execute_create
    conn.execute(stmt)
sqlite3.OperationalError: table "orders_fact" already exists
2023-04-19 19:09:35,891 - utils.database - INFO -> Sending new connection
2023-04-19 19:09:35,898 - __main__ - INFO -> Reading Data file
2023-04-19 19:09:35,903 - __main__ - INFO -> Reading Data file
2023-04-19 19:12:30,506 - utils.database - INFO -> Sending new connection
2023-04-19 19:12:30,515 - __main__ - INFO -> Reading Data file
2023-04-19 19:12:30,520 - __main__ - INFO -> Reading Data file
2023-04-19 19:13:39,648 - utils.database - INFO -> Sending new connection
2023-04-19 19:13:39,701 - __main__ - INFO -> Reading Data file
2023-04-19 19:13:39,719 - __main__ - INFO -> Reading Data file
2023-04-19 19:14:55,603 - utils.database - INFO -> Sending new connection
2023-04-19 19:14:55,647 - __main__ - INFO -> Reading Data file
2023-04-19 19:14:55,662 - __main__ - INFO -> Reading Data file
2023-04-19 19:16:49,801 - utils.database - INFO -> Sending new connection
2023-04-19 19:16:49,808 - __main__ - INFO -> Reading Data file
2023-04-19 19:16:49,814 - __main__ - INFO -> Reading Data file
2023-04-19 19:18:28,891 - utils.database - INFO -> Sending new connection
2023-04-19 19:18:28,900 - __main__ - INFO -> Reading Data file
2023-04-19 19:18:28,906 - __main__ - INFO -> Reading Data file
2023-04-19 19:18:28,923 - utils.database - INFO -> SELECT name FROM sqlite_master WHERE type='table' AND name='orders_fact'
2023-04-19 19:18:28,931 - __main__ - ERROR -> Failed to ingest data in Orders table!
Traceback (most recent call last):
  File "d:\project\main.py", line 78, in order_ingestion
    required_df.to_sql(name='orders_fact', con=conn, if_exists='append', index=False)
  File "C:\Users\Administrator\AppData\Local\Programs\Python\Python311\Lib\site-packages\pandas\core\generic.py", line 2987, in to_sql
    return sql.to_sql(
           ^^^^^^^^^^^
  File "C:\Users\Administrator\AppData\Local\Programs\Python\Python311\Lib\site-packages\pandas\io\sql.py", line 695, in to_sql
    return pandas_sql.to_sql(
           ^^^^^^^^^^^^^^^^^^
  File "C:\Users\Administrator\AppData\Local\Programs\Python\Python311\Lib\site-packages\pandas\io\sql.py", line 2187, in to_sql
    table.create()
  File "C:\Users\Administrator\AppData\Local\Programs\Python\Python311\Lib\site-packages\pandas\io\sql.py", line 838, in create
    self._execute_create()
  File "C:\Users\Administrator\AppData\Local\Programs\Python\Python311\Lib\site-packages\pandas\io\sql.py", line 1871, in _execute_create
    conn.execute(stmt)
sqlite3.OperationalError: table "orders_fact" already exists
2023-04-19 19:21:46,532 - utils.database - INFO -> Sending new connection
2023-04-19 19:21:46,541 - __main__ - INFO -> Reading Data file
2023-04-19 19:21:46,545 - __main__ - INFO -> Reading Data file
2023-04-19 19:21:46,562 - utils.database - INFO -> SELECT name FROM sqlite_master WHERE type='table' AND name='orders_fact'
2023-04-19 19:21:46,564 - __main__ - INFO -> Index(['order_number', 'client_name', 'product_name', 'product_type',
       'unit_price', 'product_quantity', 'total_price', 'currency',
       'payment_type', 'payment_billing_code', 'payment_date'],
      dtype='object')
2023-04-19 19:21:46,565 - __main__ - INFO ->   order_number   client_name  ... payment_billing_code payment_date
0  PO0060504-1  Macgyver inc  ...   PO0060504-20210321    3/21/2021
1  PO0060504-2    Howell llc  ...   PO0087294-20210317    3/17/2021
2  PO0060504-3    Howell llc  ...   PO0087294-20210317    3/17/2021
3  PO0060504-4    Howell llc  ...   PO0087294-20210317    3/17/2021
4  PO0060504-5    Howell llc  ...   PO0087294-20210317    3/17/2021

[5 rows x 11 columns]
2023-04-19 19:21:46,613 - __main__ - ERROR -> Failed to ingest data in Orders table!
Traceback (most recent call last):
  File "d:\project\main.py", line 80, in order_ingestion
    required_df.to_sql(name='orders_fact', con=conn, if_exists='append', index=False)
  File "C:\Users\Administrator\AppData\Local\Programs\Python\Python311\Lib\site-packages\pandas\core\generic.py", line 2987, in to_sql
    return sql.to_sql(
           ^^^^^^^^^^^
  File "C:\Users\Administrator\AppData\Local\Programs\Python\Python311\Lib\site-packages\pandas\io\sql.py", line 695, in to_sql
    return pandas_sql.to_sql(
           ^^^^^^^^^^^^^^^^^^
  File "C:\Users\Administrator\AppData\Local\Programs\Python\Python311\Lib\site-packages\pandas\io\sql.py", line 2187, in to_sql
    table.create()
  File "C:\Users\Administrator\AppData\Local\Programs\Python\Python311\Lib\site-packages\pandas\io\sql.py", line 838, in create
    self._execute_create()
  File "C:\Users\Administrator\AppData\Local\Programs\Python\Python311\Lib\site-packages\pandas\io\sql.py", line 1871, in _execute_create
    conn.execute(stmt)
sqlite3.OperationalError: table "orders_fact" already exists
2023-04-19 19:22:21,085 - utils.database - INFO -> Sending new connection
2023-04-19 19:22:21,096 - __main__ - INFO -> Reading Data file
2023-04-19 19:22:21,101 - __main__ - INFO -> Reading Data file
2023-04-19 19:22:21,112 - utils.database - INFO -> SELECT name FROM sqlite_master WHERE type='table' AND name='orders_fact'
2023-04-19 19:22:21,113 - __main__ - INFO -> Index(['order_number', 'client_name', 'product_name', 'product_type',
       'unit_price', 'product_quantity', 'total_price', 'currency',
       'payment_type', 'payment_billing_code', 'payment_date'],
      dtype='object')
2023-04-19 19:22:21,114 - __main__ - INFO -> order_number            object
client_name             object
product_name            object
product_type            object
unit_price              object
product_quantity        object
total_price             object
currency                object
payment_type            object
payment_billing_code    object
payment_date            object
dtype: object
2023-04-19 19:22:21,116 - __main__ - INFO ->   order_number   client_name  ... payment_billing_code payment_date
0  PO0060504-1  Macgyver inc  ...   PO0060504-20210321    3/21/2021
1  PO0060504-2    Howell llc  ...   PO0087294-20210317    3/17/2021
2  PO0060504-3    Howell llc  ...   PO0087294-20210317    3/17/2021
3  PO0060504-4    Howell llc  ...   PO0087294-20210317    3/17/2021
4  PO0060504-5    Howell llc  ...   PO0087294-20210317    3/17/2021

[5 rows x 11 columns]
2023-04-19 19:22:21,170 - __main__ - ERROR -> Failed to ingest data in Orders table!
Traceback (most recent call last):
  File "d:\project\main.py", line 81, in order_ingestion
    required_df.to_sql(name='orders_fact', con=conn, if_exists='append', index=False)
  File "C:\Users\Administrator\AppData\Local\Programs\Python\Python311\Lib\site-packages\pandas\core\generic.py", line 2987, in to_sql
    return sql.to_sql(
           ^^^^^^^^^^^
  File "C:\Users\Administrator\AppData\Local\Programs\Python\Python311\Lib\site-packages\pandas\io\sql.py", line 695, in to_sql
    return pandas_sql.to_sql(
           ^^^^^^^^^^^^^^^^^^
  File "C:\Users\Administrator\AppData\Local\Programs\Python\Python311\Lib\site-packages\pandas\io\sql.py", line 2187, in to_sql
    table.create()
  File "C:\Users\Administrator\AppData\Local\Programs\Python\Python311\Lib\site-packages\pandas\io\sql.py", line 838, in create
    self._execute_create()
  File "C:\Users\Administrator\AppData\Local\Programs\Python\Python311\Lib\site-packages\pandas\io\sql.py", line 1871, in _execute_create
    conn.execute(stmt)
sqlite3.OperationalError: table "orders_fact" already exists
2023-04-19 19:25:03,172 - utils.database - INFO -> Sending new connection
2023-04-19 19:25:03,219 - __main__ - INFO -> Reading Data file
2023-04-19 19:25:03,233 - __main__ - INFO -> Reading Data file
2023-04-19 19:30:48,321 - utils.database - INFO -> Sending new connection
2023-04-19 19:30:48,367 - __main__ - INFO -> Reading Data file
2023-04-19 19:30:48,385 - __main__ - INFO -> Reading Data file
2023-04-19 19:32:37,699 - utils.database - INFO -> Sending new connection
2023-04-19 19:32:37,707 - __main__ - INFO -> Reading Data file
2023-04-19 19:32:37,711 - __main__ - INFO -> Reading Data file
2023-04-19 19:32:37,719 - utils.database - INFO -> SELECT name FROM sqlite_master WHERE type='table' AND name='orders_fact'
2023-04-19 19:32:37,720 - __main__ - INFO -> Index(['order_number', 'client_name', 'product_name', 'product_type',
       'unit_price', 'product_quantity', 'total_price', 'currency',
       'payment_type', 'payment_billing_code', 'payment_date'],
      dtype='object')
2023-04-19 19:32:37,721 - __main__ - INFO -> order_number             object
client_name              object
product_name             object
product_type             object
unit_price              float64
product_quantity          int64
total_price             float64
currency                 object
payment_type             object
payment_billing_code     object
payment_date             object
dtype: object
2023-04-19 19:32:37,726 - __main__ - INFO ->   order_number   client_name  product_name  ... payment_type  payment_billing_code  payment_date
0  PO0060504-1  Macgyver inc         Piano  ...        Debit    PO0060504-20210321     3/21/2021
1  PO0060504-2    Howell llc  Bamboo flute  ...       Credit    PO0087294-20210317     3/17/2021
2  PO0060504-3    Howell llc          Harp  ...       Credit    PO0087294-20210317     3/17/2021
3  PO0060504-4    Howell llc         Piano  ...       Credit    PO0087294-20210317     3/17/2021
4  PO0060504-5    Howell llc    Snare drum  ...       Credit    PO0087294-20210317     3/17/2021

[5 rows x 11 columns]
2023-04-19 19:32:37,764 - __main__ - ERROR -> Failed to ingest data in Orders table!
Traceback (most recent call last):
  File "d:\project\main.py", line 81, in order_ingestion
    required_df.to_sql(name='orders_fact', con=conn, if_exists='append', index=False)
  File "C:\Users\Administrator\AppData\Local\Programs\Python\Python311\Lib\site-packages\pandas\core\generic.py", line 2987, in to_sql
    return sql.to_sql(
           ^^^^^^^^^^^
  File "C:\Users\Administrator\AppData\Local\Programs\Python\Python311\Lib\site-packages\pandas\io\sql.py", line 695, in to_sql
    return pandas_sql.to_sql(
           ^^^^^^^^^^^^^^^^^^
  File "C:\Users\Administrator\AppData\Local\Programs\Python\Python311\Lib\site-packages\pandas\io\sql.py", line 2187, in to_sql
    table.create()
  File "C:\Users\Administrator\AppData\Local\Programs\Python\Python311\Lib\site-packages\pandas\io\sql.py", line 838, in create
    self._execute_create()
  File "C:\Users\Administrator\AppData\Local\Programs\Python\Python311\Lib\site-packages\pandas\io\sql.py", line 1871, in _execute_create
    conn.execute(stmt)
sqlite3.OperationalError: table "orders_fact" already exists
2023-04-19 19:48:13,996 - utils.database - INFO -> Sending new connection
2023-04-19 19:48:14,012 - __main__ - INFO -> Reading Data file
2023-04-19 19:48:14,020 - __main__ - INFO -> Reading Data file
2023-04-19 19:48:14,027 - utils.database - INFO -> SELECT name FROM sqlite_master WHERE type='table' AND name='orders_fact'
2023-04-19 19:48:14,028 - __main__ - INFO -> Index(['order_number', 'client_name', 'product_name', 'product_type',
       'unit_price', 'product_quantity', 'total_price', 'currency',
       'payment_type', 'payment_billing_code', 'payment_date'],
      dtype='object')
2023-04-19 19:48:14,029 - __main__ - INFO -> order_number             object
client_name              object
product_name             object
product_type             object
unit_price              float64
product_quantity          int64
total_price             float64
currency                 object
payment_type             object
payment_billing_code     object
payment_date             object
dtype: object
2023-04-19 19:48:14,034 - __main__ - INFO ->   order_number   client_name  product_name product_type  ...  currency  payment_type  payment_billing_code payment_date
0  PO0060504-1  Macgyver inc         Piano     Keyboard  ...       Gbp         Debit    PO0060504-20210321    3/21/2021
1  PO0060504-2    Howell llc  Bamboo flute     Woodwind  ...       Gbp        Credit    PO0087294-20210317    3/17/2021
2  PO0060504-3    Howell llc          Harp       String  ...       Gbp        Credit    PO0087294-20210317    3/17/2021
3  PO0060504-4    Howell llc         Piano     Keyboard  ...       Gbp        Credit    PO0087294-20210317    3/17/2021
4  PO0060504-5    Howell llc    Snare drum   Percussion  ...       Gbp        Credit    PO0087294-20210317    3/17/2021

[5 rows x 11 columns]
2023-04-19 19:48:14,072 - __main__ - ERROR -> Failed to ingest data in Orders table!
Traceback (most recent call last):
  File "d:\project\main.py", line 81, in order_ingestion
    required_df.to_sql(name='orders_fact', con=conn, if_exists='append', index=False)
  File "C:\Users\Administrator\AppData\Local\Programs\Python\Python311\Lib\site-packages\pandas\core\generic.py", line 2878, in to_sql
    return sql.to_sql(
           ^^^^^^^^^^^
  File "C:\Users\Administrator\AppData\Local\Programs\Python\Python311\Lib\site-packages\pandas\io\sql.py", line 767, in to_sql
    return pandas_sql.to_sql(
           ^^^^^^^^^^^^^^^^^^
  File "C:\Users\Administrator\AppData\Local\Programs\Python\Python311\Lib\site-packages\pandas\io\sql.py", line 2376, in to_sql
    table.create()
  File "C:\Users\Administrator\AppData\Local\Programs\Python\Python311\Lib\site-packages\pandas\io\sql.py", line 912, in create
    self._execute_create()
  File "C:\Users\Administrator\AppData\Local\Programs\Python\Python311\Lib\site-packages\pandas\io\sql.py", line 2050, in _execute_create
    conn.execute(stmt)
sqlite3.OperationalError: table "orders_fact" already exists
2023-04-19 19:55:35,786 - utils.database - INFO -> Sending new connection
2023-04-19 19:55:35,798 - __main__ - INFO -> Reading Data file
2023-04-19 19:55:35,805 - __main__ - INFO -> Reading Data file
2023-04-19 19:55:35,812 - utils.database - INFO -> SELECT name FROM sqlite_master WHERE type='table' AND name='orders_fact'
2023-04-19 19:55:35,813 - __main__ - INFO -> Index(['order_number', 'client_name', 'product_name', 'product_type',
       'unit_price', 'product_quantity', 'total_price', 'currency',
       'payment_type', 'payment_billing_code', 'payment_date'],
      dtype='object')
2023-04-19 19:55:35,814 - __main__ - INFO -> order_number             object
client_name              object
product_name             object
product_type             object
unit_price              float64
product_quantity          int64
total_price             float64
currency                 object
payment_type             object
payment_billing_code     object
payment_date             object
dtype: object
2023-04-19 19:55:35,820 - __main__ - INFO ->   order_number   client_name  product_name  ... payment_type  payment_billing_code  payment_date
0  PO0060504-1  Macgyver inc         Piano  ...        Debit    PO0060504-20210321     3/21/2021
1  PO0060504-2    Howell llc  Bamboo flute  ...       Credit    PO0087294-20210317     3/17/2021
2  PO0060504-3    Howell llc          Harp  ...       Credit    PO0087294-20210317     3/17/2021
3  PO0060504-4    Howell llc         Piano  ...       Credit    PO0087294-20210317     3/17/2021
4  PO0060504-5    Howell llc    Snare drum  ...       Credit    PO0087294-20210317     3/17/2021

[5 rows x 11 columns]
2023-04-19 19:55:35,863 - __main__ - ERROR -> Failed to ingest data in Orders table!
Traceback (most recent call last):
  File "d:\project\main.py", line 81, in order_ingestion
    required_df.to_sql(name='orders_fact', con=conn, if_exists='append', index=False)
  File "C:\Users\Administrator\AppData\Local\Programs\Python\Python311\Lib\site-packages\pandas\core\generic.py", line 2878, in to_sql
    return sql.to_sql(
           ^^^^^^^^^^^
  File "C:\Users\Administrator\AppData\Local\Programs\Python\Python311\Lib\site-packages\pandas\io\sql.py", line 767, in to_sql
    return pandas_sql.to_sql(
           ^^^^^^^^^^^^^^^^^^
  File "C:\Users\Administrator\AppData\Local\Programs\Python\Python311\Lib\site-packages\pandas\io\sql.py", line 2376, in to_sql
    table.create()
  File "C:\Users\Administrator\AppData\Local\Programs\Python\Python311\Lib\site-packages\pandas\io\sql.py", line 912, in create
    self._execute_create()
  File "C:\Users\Administrator\AppData\Local\Programs\Python\Python311\Lib\site-packages\pandas\io\sql.py", line 2050, in _execute_create
    conn.execute(stmt)
sqlite3.OperationalError: table "orders_fact" already exists
2023-04-19 20:17:48,315 - utils.database - INFO -> Sending new connection
2023-04-19 20:17:48,327 - __main__ - INFO -> Reading Data file
2023-04-19 20:17:48,334 - __main__ - INFO -> Reading Data file
2023-04-19 20:17:48,344 - utils.database - INFO -> SELECT name FROM sqlite_master WHERE type='table' AND name='orders_fact'
2023-04-19 20:17:48,346 - __main__ - INFO -> Index(['order_number', 'client_name', 'product_name', 'product_type',
       'unit_price', 'product_quantity', 'total_price', 'currency',
       'payment_type', 'payment_billing_code', 'payment_date'],
      dtype='object')
2023-04-19 20:17:48,347 - __main__ - INFO -> order_number             object
client_name              object
product_name             object
product_type             object
unit_price              float64
product_quantity          int64
total_price             float64
currency                 object
payment_type             object
payment_billing_code     object
payment_date             object
dtype: object
2023-04-19 20:17:48,351 - __main__ - INFO ->   order_number   client_name  product_name  ... payment_type  payment_billing_code  payment_date
0  PO0060504-1  Macgyver inc         Piano  ...        Debit    PO0060504-20210321     3/21/2021
1  PO0060504-2    Howell llc  Bamboo flute  ...       Credit    PO0087294-20210317     3/17/2021
2  PO0060504-3    Howell llc          Harp  ...       Credit    PO0087294-20210317     3/17/2021
3  PO0060504-4    Howell llc         Piano  ...       Credit    PO0087294-20210317     3/17/2021
4  PO0060504-5    Howell llc    Snare drum  ...       Credit    PO0087294-20210317     3/17/2021

[5 rows x 11 columns]
2023-04-19 20:17:48,397 - __main__ - ERROR -> Failed to ingest data in Orders table!
Traceback (most recent call last):
  File "d:\project\main.py", line 78, in order_ingestion
    required_df.to_sql(name='orders_fact', con=conn, if_exists='append', index=False)
  File "C:\Users\Administrator\AppData\Local\Programs\Python\Python311\Lib\site-packages\pandas\core\generic.py", line 2878, in to_sql
    return sql.to_sql(
           ^^^^^^^^^^^
  File "C:\Users\Administrator\AppData\Local\Programs\Python\Python311\Lib\site-packages\pandas\io\sql.py", line 767, in to_sql
    return pandas_sql.to_sql(
           ^^^^^^^^^^^^^^^^^^
  File "C:\Users\Administrator\AppData\Local\Programs\Python\Python311\Lib\site-packages\pandas\io\sql.py", line 2377, in to_sql
    return table.insert(chunksize, method)
           ^^^^^^^^^^^^^^^^^^^^^^^^^^^^^^^
  File "C:\Users\Administrator\AppData\Local\Programs\Python\Python311\Lib\site-packages\pandas\io\sql.py", line 1021, in insert
    num_inserted = exec_insert(conn, keys, chunk_iter)
                   ^^^^^^^^^^^^^^^^^^^^^^^^^^^^^^^^^^^
  File "C:\Users\Administrator\AppData\Local\Programs\Python\Python311\Lib\site-packages\pandas\io\sql.py", line 2073, in _execute_insert
    conn.executemany(self.insert_statement(num_rows=1), data_list)
sqlite3.IntegrityError: UNIQUE constraint failed: orders_fact.order_number
2023-04-19 20:19:21,038 - utils.database - INFO -> Sending new connection
2023-04-19 20:19:21,044 - __main__ - INFO -> Reading Data file
2023-04-19 20:19:21,052 - __main__ - INFO -> Reading Data file
2023-04-19 20:19:21,066 - utils.database - INFO -> SELECT name FROM sqlite_master WHERE type='table' AND name='orders_fact'
2023-04-19 20:19:21,082 - __main__ - INFO -> Index(['order_number', 'client_name', 'product_name', 'product_type',
       'unit_price', 'product_quantity', 'total_price', 'currency',
       'payment_type', 'payment_billing_code', 'payment_date'],
      dtype='object')
2023-04-19 20:19:21,084 - __main__ - INFO -> order_number             object
client_name              object
product_name             object
product_type             object
unit_price              float64
product_quantity          int64
total_price             float64
currency                 object
payment_type             object
payment_billing_code     object
payment_date             object
dtype: object
2023-04-19 20:19:21,087 - __main__ - INFO ->   order_number   client_name  product_name  ... payment_type  payment_billing_code  payment_date
0  PO0060504-1  Macgyver inc         Piano  ...        Debit    PO0060504-20210321     3/21/2021
1  PO0060504-2    Howell llc  Bamboo flute  ...       Credit    PO0087294-20210317     3/17/2021
2  PO0060504-3    Howell llc          Harp  ...       Credit    PO0087294-20210317     3/17/2021
3  PO0060504-4    Howell llc         Piano  ...       Credit    PO0087294-20210317     3/17/2021
4  PO0060504-5    Howell llc    Snare drum  ...       Credit    PO0087294-20210317     3/17/2021

[5 rows x 11 columns]
2023-04-19 23:03:51,004 - utils.database - INFO -> Sending new connection
2023-04-19 23:03:51,033 - __main__ - INFO -> Reading Data file
2023-04-19 23:03:51,047 - __main__ - INFO -> Reading Data file
2023-04-19 23:06:26,637 - utils.database - INFO -> Sending new connection
2023-04-19 23:06:26,644 - __main__ - INFO -> Reading Data file
2023-04-19 23:06:26,650 - __main__ - INFO -> Reading Data file
2023-04-19 23:06:26,661 - __main__ - INFO -> Validations passed
2023-04-19 23:06:26,662 - utils.database - INFO -> SELECT name FROM sqlite_master WHERE type='table' AND name='orders_fact'
2023-04-19 23:06:26,664 - __main__ - INFO -> Index(['order_number', 'client_name', 'product_name', 'product_type',
       'unit_price', 'product_quantity', 'total_price', 'currency',
       'payment_type', 'payment_billing_code', 'payment_date'],
      dtype='object')
2023-04-19 23:06:26,666 - __main__ - INFO -> order_number             object
client_name              object
product_name             object
product_type             object
unit_price              float64
product_quantity          int64
total_price             float64
currency                 object
payment_type             object
payment_billing_code     object
payment_date             object
dtype: object
2023-04-19 23:06:26,669 - __main__ - INFO ->   order_number   client_name  product_name product_type  unit_price  ...  total_price  currency payment_type payment_billing_code payment_date
0  PO0060504-1  Macgyver inc         Piano     Keyboard      4700.0  ...      14100.0       Gbp        Debit   PO0060504-20210321    3/21/2021
1  PO0060504-2    Howell llc  Bamboo flute     Woodwind        60.0  ...         60.0       Gbp       Credit   PO0087294-20210317    3/17/2021
2  PO0060504-3    Howell llc          Harp       String       940.0  ...       1880.0       Gbp       Credit   PO0087294-20210317    3/17/2021
3  PO0060504-4    Howell llc         Piano     Keyboard      4700.0  ...       9400.0       Gbp       Credit   PO0087294-20210317    3/17/2021
4  PO0060504-5    Howell llc    Snare drum   Percussion       350.0  ...       1050.0       Gbp       Credit   PO0087294-20210317    3/17/2021

[5 rows x 11 columns]
2023-04-19 23:06:26,714 - __main__ - ERROR -> Failed to ingest data in Orders table!
Traceback (most recent call last):
  File "d:\project\main.py", line 106, in order_ingestion
    required_df.to_sql(name='orders_fact', con=conn, if_exists='append', index=False)
  File "C:\Users\Administrator\AppData\Local\Programs\Python\Python311\Lib\site-packages\pandas\core\generic.py", line 2878, in to_sql
    return sql.to_sql(
           ^^^^^^^^^^^
  File "C:\Users\Administrator\AppData\Local\Programs\Python\Python311\Lib\site-packages\pandas\io\sql.py", line 767, in to_sql
    return pandas_sql.to_sql(
           ^^^^^^^^^^^^^^^^^^
  File "C:\Users\Administrator\AppData\Local\Programs\Python\Python311\Lib\site-packages\pandas\io\sql.py", line 2377, in to_sql
    return table.insert(chunksize, method)
           ^^^^^^^^^^^^^^^^^^^^^^^^^^^^^^^
  File "C:\Users\Administrator\AppData\Local\Programs\Python\Python311\Lib\site-packages\pandas\io\sql.py", line 1021, in insert
    num_inserted = exec_insert(conn, keys, chunk_iter)
                   ^^^^^^^^^^^^^^^^^^^^^^^^^^^^^^^^^^^
  File "C:\Users\Administrator\AppData\Local\Programs\Python\Python311\Lib\site-packages\pandas\io\sql.py", line 2073, in _execute_insert
    conn.executemany(self.insert_statement(num_rows=1), data_list)
sqlite3.IntegrityError: UNIQUE constraint failed: orders_fact.order_number
2023-04-19 23:33:18,845 - utils.database - INFO -> Sending new connection
2023-04-19 23:33:18,854 - __main__ - INFO -> Reading Data file
2023-04-19 23:33:18,861 - __main__ - INFO -> Reading Data file
2023-04-19 23:33:18,874 - __main__ - INFO -> Validations passed
2023-04-19 23:33:18,874 - utils.database - INFO -> SELECT name FROM sqlite_master WHERE type='table' AND name='orders_fact'
2023-04-19 23:34:09,640 - utils.database - INFO -> Sending new connection
2023-04-19 23:34:09,649 - __main__ - INFO -> Reading Data file
2023-04-19 23:34:09,657 - __main__ - INFO -> Reading Data file
2023-04-19 23:34:09,671 - __main__ - INFO -> Validations passed
2023-04-19 23:34:09,673 - utils.database - INFO -> SELECT name FROM sqlite_master WHERE type='table' AND name='orders_fact'
2023-04-19 23:56:37,602 - utils.database - INFO -> Sending new connection
2023-04-19 23:56:37,609 - __main__ - INFO -> Reading Data file
2023-04-19 23:56:37,616 - __main__ - INFO -> Reading Data file
2023-04-19 23:56:37,645 - __main__ - INFO -> Validations passed
2023-04-19 23:56:37,645 - utils.database - INFO -> SELECT name FROM sqlite_master WHERE type='table' AND name='orders_fact'
2023-04-19 23:56:37,688 - __main__ - ERROR -> Failed to ingest data in Orders table!
Traceback (most recent call last):
  File "d:\project\main.py", line 107, in order_ingestion
    db_obj.select(sql_file="sql/orders_fact_ingestion.sql")
TypeError: Database.select() got an unexpected keyword argument 'sql_file'
2023-04-20 00:04:11,680 - utils.database - INFO -> Sending new connection
2023-04-20 00:04:11,689 - __main__ - INFO -> Reading Data file
2023-04-20 00:04:11,697 - __main__ - INFO -> Reading Data file
2023-04-20 00:04:11,709 - __main__ - INFO -> Validations passed
2023-04-20 00:04:11,710 - utils.database - INFO -> SELECT name FROM sqlite_master WHERE type='table' AND name='orders_fact'
2023-04-20 00:04:11,752 - __main__ - ERROR -> Failed to ingest data in Orders table!
Traceback (most recent call last):
  File "d:\project\main.py", line 107, in order_ingestion
    db_obj.delete(table_name="orders_fact", filter_clause="order_number in ( SELECT order_number from stg_orders_fact)")
  File "d:\project\utils\database.py", line 96, in delete
    cursor.execute(delete_query)
sqlite3.OperationalError: near "order_number": syntax error
2023-04-20 00:05:39,376 - utils.database - INFO -> Sending new connection
2023-04-20 00:05:39,398 - __main__ - INFO -> Reading Data file
2023-04-20 00:05:39,405 - __main__ - INFO -> Reading Data file
2023-04-20 00:05:39,421 - __main__ - INFO -> Validations passed
2023-04-20 00:05:39,422 - utils.database - INFO -> SELECT name FROM sqlite_master WHERE type='table' AND name='orders_fact'
2023-04-20 00:05:39,462 - utils.database - INFO -> DELETE FROM orders_factWHERE order_number in ( SELECT order_number from stg_orders_fact)
2023-04-20 00:05:39,463 - __main__ - ERROR -> Failed to ingest data in Orders table!
Traceback (most recent call last):
  File "d:\project\main.py", line 107, in order_ingestion
    db_obj.delete(table_name="orders_fact", filter_clause="order_number in ( SELECT order_number from stg_orders_fact)")
  File "d:\project\utils\database.py", line 97, in delete
    cursor.execute(delete_query)
sqlite3.OperationalError: near "order_number": syntax error
2023-04-20 00:06:04,419 - utils.database - INFO -> Sending new connection
2023-04-20 00:06:04,428 - __main__ - INFO -> Reading Data file
2023-04-20 00:06:04,433 - __main__ - INFO -> Reading Data file
2023-04-20 00:06:04,449 - __main__ - INFO -> Validations passed
2023-04-20 00:06:04,449 - utils.database - INFO -> SELECT name FROM sqlite_master WHERE type='table' AND name='orders_fact'
2023-04-20 00:06:04,492 - utils.database - INFO -> DELETE FROM orders_fact WHERE order_number in ( SELECT order_number from stg_orders_fact)
2023-04-20 00:06:04,505 - __main__ - ERROR -> Failed to ingest data in Orders table!
Traceback (most recent call last):
  File "d:\project\main.py", line 108, in order_ingestion
    db_obj.insert(sql_file="sql/ddl_orders_fact_ingestion.sql")
  File "d:\project\utils\database.py", line 44, in insert
    cursor = conn.cursor()
             ^^^^^^^^^^^^^
sqlite3.ProgrammingError: Cannot operate on a closed database.
2023-04-20 00:10:27,786 - utils.database - INFO -> Sending new connection
2023-04-20 00:10:27,831 - __main__ - INFO -> Reading Data file
2023-04-20 00:10:27,844 - __main__ - INFO -> Reading Data file
2023-04-20 00:10:27,878 - __main__ - INFO -> Validations passed
2023-04-20 00:10:27,879 - utils.database - INFO -> SELECT name FROM sqlite_master WHERE type='table' AND name='orders_fact'
2023-04-20 00:10:44,928 - utils.database - INFO -> DELETE FROM orders_fact WHERE order_number in ( SELECT order_number from stg_orders_fact)
2023-04-20 00:14:16,677 - utils.database - INFO -> Sending new connection
2023-04-20 00:14:16,718 - __main__ - INFO -> Reading Data file
2023-04-20 00:14:16,733 - __main__ - INFO -> Reading Data file
2023-04-20 00:14:16,774 - __main__ - INFO -> Validations passed
2023-04-20 00:14:16,775 - utils.database - INFO -> SELECT name FROM sqlite_master WHERE type='table' AND name='orders_fact'
2023-04-20 00:14:57,434 - utils.database - INFO -> DELETE FROM orders_fact WHERE order_number in ( SELECT order_number from stg_orders_fact)
2023-04-20 00:17:32,448 - utils.database - INFO -> Sending new connection
2023-04-20 00:17:32,467 - __main__ - INFO -> Reading Data file
2023-04-20 00:17:32,472 - __main__ - INFO -> Reading Data file
2023-04-20 00:17:32,485 - __main__ - INFO -> Validations passed
2023-04-20 00:17:32,485 - utils.database - INFO -> SELECT name FROM sqlite_master WHERE type='table' AND name='orders_fact'
2023-04-20 00:17:32,549 - utils.database - INFO -> DELETE FROM orders_fact WHERE order_number in ( SELECT order_number from stg_orders_fact)
2023-04-20 00:17:32,550 - __main__ - ERROR -> Failed to ingest data in Orders table!
Traceback (most recent call last):
  File "d:\project\main.py", line 108, in order_ingestion
    db_obj.insert(sql_file="sql/ddl_orders_fact_ingestion.sql")
  File "d:\project\utils\database.py", line 47, in insert
    with open(sql_file, 'r') as f:
         ^^^^^^^^^^^^^^^^^^^
FileNotFoundError: [Errno 2] No such file or directory: 'sql/ddl_orders_fact_ingestion.sql'
2023-04-20 00:18:00,615 - utils.database - INFO -> Sending new connection
2023-04-20 00:18:00,624 - __main__ - INFO -> Reading Data file
2023-04-20 00:18:00,629 - __main__ - INFO -> Reading Data file
2023-04-20 00:18:00,646 - __main__ - INFO -> Validations passed
2023-04-20 00:18:00,646 - utils.database - INFO -> SELECT name FROM sqlite_master WHERE type='table' AND name='orders_fact'
2023-04-20 00:18:00,714 - utils.database - INFO -> DELETE FROM orders_fact WHERE order_number in ( SELECT order_number from stg_orders_fact)
2023-04-20 17:00:51,336 - utils.database - INFO -> Sending new connection
2023-04-20 17:02:10,690 - utils.database - INFO -> Sending new connection
2023-04-20 17:02:10,721 - __main__ - INFO -> Reading Data file
2023-04-20 17:02:10,752 - __main__ - INFO -> Reading Data file
2023-04-20 17:02:10,782 - __main__ - INFO -> Column: client_name failed the duplicate check.
2023-04-20 17:02:10,783 - __main__ - INFO -> Validations failed
2023-04-20 17:03:29,762 - utils.database - INFO -> Sending new connection
2023-04-20 17:03:29,774 - __main__ - INFO -> Reading Data file
2023-04-20 17:03:29,779 - __main__ - INFO -> Reading Data file
2023-04-20 17:04:03,845 - utils.database - INFO -> Sending new connection
2023-04-20 17:04:03,860 - __main__ - INFO -> Reading Data file
2023-04-20 17:04:03,868 - __main__ - INFO -> Reading Data file
2023-04-20 17:04:20,925 - utils.database - INFO -> Sending new connection
2023-04-20 17:04:20,971 - __main__ - INFO -> Reading Data file
2023-04-20 17:04:20,987 - __main__ - INFO -> Reading Data file
2023-04-20 17:10:27,450 - utils.database - INFO -> Sending new connection
2023-04-20 17:10:27,460 - __main__ - INFO -> Reading Data file
2023-04-20 17:10:27,465 - __main__ - INFO -> Reading Data file
2023-04-20 17:10:27,475 - __main__ - INFO -> Validations passed
2023-04-20 17:10:27,475 - utils.database - INFO -> SELECT name FROM sqlite_master WHERE type='table' AND name='client_dim'
2023-04-20 17:11:21,880 - utils.database - INFO -> Sending new connection
2023-04-20 17:11:21,890 - __main__ - INFO -> Reading Data file
2023-04-20 17:11:21,897 - __main__ - INFO -> Reading Data file
2023-04-20 17:11:21,908 - __main__ - INFO -> Validations passed
2023-04-20 17:11:21,908 - utils.database - INFO -> SELECT name FROM sqlite_master WHERE type='table' AND name='client_dim'
2023-04-20 17:11:21,923 - __main__ - INFO -> Client Dim ingestion kicks in
2023-04-20 17:11:21,957 - __main__ - ERROR -> Failed to ingest.
Traceback (most recent call last):
  File "d:\project\main.py", line 85, in client_ingestion
    required_df.to_sql(name="stage_client_dim", con=conn)
  File "C:\Users\Administrator\AppData\Local\Programs\Python\Python311\Lib\site-packages\pandas\core\generic.py", line 2878, in to_sql
    return sql.to_sql(
           ^^^^^^^^^^^
  File "C:\Users\Administrator\AppData\Local\Programs\Python\Python311\Lib\site-packages\pandas\io\sql.py", line 767, in to_sql
    return pandas_sql.to_sql(
           ^^^^^^^^^^^^^^^^^^
  File "C:\Users\Administrator\AppData\Local\Programs\Python\Python311\Lib\site-packages\pandas\io\sql.py", line 2376, in to_sql
    table.create()
  File "C:\Users\Administrator\AppData\Local\Programs\Python\Python311\Lib\site-packages\pandas\io\sql.py", line 903, in create
    raise ValueError(f"Table '{self.name}' already exists.")
ValueError: Table 'stage_client_dim' already exists.
2023-04-20 17:16:02,103 - utils.database - INFO -> Sending new connection
2023-04-20 17:16:02,114 - __main__ - INFO -> Reading Data file
2023-04-20 17:16:02,119 - __main__ - INFO -> Reading Data file
2023-04-20 17:16:02,127 - __main__ - INFO -> Validations passed
2023-04-20 17:16:02,128 - utils.database - INFO -> SELECT name FROM sqlite_master WHERE type='table' AND name='client_dim'
2023-04-20 17:16:02,130 - __main__ - INFO -> Client Dim ingestion kicks in...
2023-04-20 17:17:06,733 - utils.database - INFO -> Sending new connection
2023-04-20 17:17:06,745 - __main__ - INFO -> Reading Data file
2023-04-20 17:17:06,750 - __main__ - INFO -> Reading Data file
2023-04-20 17:17:06,758 - __main__ - INFO -> Validations passed
2023-04-20 17:17:06,760 - utils.database - INFO -> SELECT name FROM sqlite_master WHERE type='table' AND name='client_dim'
2023-04-20 17:17:06,763 - __main__ - INFO -> Client Dim ingestion kicks in...
2023-04-20 17:17:06,801 - __main__ - ERROR -> Failed to ingest.
Traceback (most recent call last):
  File "d:\project\main.py", line 85, in client_ingestion
    required_df.to_sql(name="stage_client_dim", con=conn)
  File "C:\Users\Administrator\AppData\Local\Programs\Python\Python311\Lib\site-packages\pandas\core\generic.py", line 2878, in to_sql
    return sql.to_sql(
           ^^^^^^^^^^^
  File "C:\Users\Administrator\AppData\Local\Programs\Python\Python311\Lib\site-packages\pandas\io\sql.py", line 767, in to_sql
    return pandas_sql.to_sql(
           ^^^^^^^^^^^^^^^^^^
  File "C:\Users\Administrator\AppData\Local\Programs\Python\Python311\Lib\site-packages\pandas\io\sql.py", line 2376, in to_sql
    table.create()
  File "C:\Users\Administrator\AppData\Local\Programs\Python\Python311\Lib\site-packages\pandas\io\sql.py", line 903, in create
    raise ValueError(f"Table '{self.name}' already exists.")
ValueError: Table 'stage_client_dim' already exists.
2023-04-20 17:26:57,306 - utils.database - INFO -> Sending new connection
2023-04-20 17:26:57,317 - __main__ - INFO -> Reading Data file
2023-04-20 17:26:57,323 - __main__ - INFO -> Reading Data file
2023-04-20 17:26:57,332 - __main__ - INFO -> Validations passed
2023-04-20 17:26:57,334 - utils.database - INFO -> SELECT name FROM sqlite_master WHERE type='table' AND name='client_dim'
2023-04-20 17:26:57,335 - __main__ - INFO -> Client Dim ingestion kicks in...
2023-04-20 17:36:51,380 - utils.database - INFO -> Sending new connection
2023-04-20 17:36:51,390 - __main__ - INFO -> Reading Data file
2023-04-20 17:36:51,397 - __main__ - INFO -> Reading Data file
2023-04-20 17:36:51,429 - __main__ - INFO -> Validations passed
2023-04-20 17:36:51,430 - utils.database - INFO -> SELECT name FROM sqlite_master WHERE type='table' AND name='client_dim'
2023-04-20 17:36:51,433 - __main__ - INFO -> Client Dim ingestion kicks in...
2023-04-20 18:34:11,509 - utils.database - INFO -> Sending new connection
2023-04-20 18:34:11,566 - __main__ - INFO -> Reading Data file
2023-04-20 18:34:11,585 - __main__ - INFO -> Reading Data file
2023-04-20 18:34:47,359 - __main__ - INFO -> Validations passed
2023-04-20 18:34:55,405 - utils.database - INFO -> SELECT name FROM sqlite_master WHERE type='table' AND name='client_dim'
2023-04-20 18:49:32,729 - utils.database - INFO -> Sending new connection
2023-04-20 18:49:32,739 - __main__ - INFO -> Reading Data file
2023-04-20 18:49:32,746 - __main__ - INFO -> Reading Data file
2023-04-20 18:49:32,756 - __main__ - INFO -> Validations passed
2023-04-20 18:49:32,757 - utils.database - INFO -> SELECT name FROM sqlite_master WHERE type='table' AND name='client_dim'
2023-04-20 18:50:16,004 - utils.database - INFO -> Sending new connection
2023-04-20 18:50:16,014 - __main__ - INFO -> Reading Data file
2023-04-20 18:50:16,022 - __main__ - INFO -> Reading Data file
2023-04-20 18:50:16,042 - __main__ - INFO -> Validations passed
2023-04-20 18:50:16,044 - utils.database - INFO -> SELECT name FROM sqlite_master WHERE type='table' AND name='client_dim'
2023-04-20 19:04:53,755 - utils.database - INFO -> Sending new connection
2023-04-20 19:04:53,767 - __main__ - INFO -> Reading Data file
2023-04-20 19:04:53,772 - __main__ - INFO -> Reading Data file
2023-04-20 19:04:53,788 - __main__ - INFO -> Validations passed
2023-04-20 19:04:53,789 - utils.database - INFO -> SELECT name FROM sqlite_master WHERE type='table' AND name='client_dim'
2023-04-20 19:06:28,094 - utils.database - INFO -> Sending new connection
2023-04-20 19:06:28,112 - __main__ - INFO -> Reading Data file
2023-04-20 19:06:28,120 - __main__ - INFO -> Reading Data file
2023-04-20 19:06:28,130 - __main__ - INFO -> Validations passed
2023-04-20 19:06:28,130 - utils.database - INFO -> SELECT name FROM sqlite_master WHERE type='table' AND name='client_dim'
2023-04-20 21:39:49,462 - utils.database - INFO -> Sending new connection
2023-04-20 21:39:49,597 - __main__ - INFO -> Reading Data file
2023-04-20 21:39:49,613 - __main__ - INFO -> Reading Data file
2023-04-20 21:40:47,401 - __main__ - INFO -> Validations passed
2023-04-20 21:40:49,803 - utils.database - INFO -> SELECT name FROM sqlite_master WHERE type='table' AND name='client_dim'
2023-04-20 23:09:56,626 - utils.database - INFO -> Sending new connection
2023-04-20 23:09:56,678 - __main__ - INFO -> Reading Data file
2023-04-20 23:09:56,693 - __main__ - INFO -> Reading Data file
2023-04-20 23:12:26,185 - __main__ - INFO -> Validations passed
2023-04-20 23:13:03,660 - utils.database - INFO -> SELECT name FROM sqlite_master WHERE type='table' AND name='client_dim'
2023-04-20 23:14:07,358 - __main__ - INFO -> Reading Data file
2023-04-20 23:14:07,366 - __main__ - INFO -> Reading Data file
2023-04-20 23:15:12,569 - utils.database - INFO -> Sending new connection
2023-04-20 23:15:12,717 - __main__ - INFO -> Reading Data file
2023-04-20 23:15:12,789 - __main__ - INFO -> Reading Data file
2023-04-20 23:15:32,431 - __main__ - INFO -> Validations passed
2023-04-20 23:15:32,457 - utils.database - INFO -> SELECT name FROM sqlite_master WHERE type='table' AND name='client_dim'
2023-04-20 23:15:32,507 - __main__ - ERROR -> Failed to ingest data in Orders table!
Traceback (most recent call last):
  File "d:\project\main.py", line 85, in client_ingestion
    db_obj.insert(sql_file="sql/client_dim_scd_ingestion.sql")
  File "d:\project\utils\database.py", line 49, in insert
    cursor.executescript(insert_query)
sqlite3.IntegrityError: NOT NULL constraint failed: client_dim.end_date
2023-04-20 23:16:03,496 - __main__ - INFO -> Reading Data file
2023-04-20 23:16:03,508 - __main__ - INFO -> Reading Data file
2023-04-20 23:17:34,411 - __main__ - INFO -> Validations passed
2023-04-20 23:18:06,981 - utils.database - INFO -> SELECT name FROM sqlite_master WHERE type='table' AND name='client_dim'
2023-04-20 23:19:55,687 - __main__ - ERROR -> Failed to ingest data in Orders table!
Traceback (most recent call last):
  File "d:\project\main.py", line 85, in client_ingestion
    db_obj.insert(sql_file="sql/client_dim_scd_ingestion.sql")
  File "d:\project\utils\database.py", line 49, in insert
    cursor.executescript(insert_query)
sqlite3.IntegrityError: NOT NULL constraint failed: client_dim.is_current
2023-04-20 23:22:29,083 - utils.database - INFO -> Sending new connection
2023-04-20 23:22:29,140 - __main__ - INFO -> Reading Data file
2023-04-20 23:22:29,156 - __main__ - INFO -> Reading Data file
2023-04-20 23:22:38,270 - utils.database - INFO -> Sending new connection
2023-04-20 23:22:38,322 - __main__ - INFO -> Reading Data file
2023-04-20 23:22:38,337 - __main__ - INFO -> Reading Data file
2023-04-20 23:22:50,732 - __main__ - INFO -> Validations passed
2023-04-20 23:22:50,762 - utils.database - INFO -> SELECT name FROM sqlite_master WHERE type='table' AND name='client_dim'
2023-04-20 23:22:50,811 - __main__ - ERROR -> Failed to ingest data in Orders table!
Traceback (most recent call last):
  File "d:\project\main.py", line 85, in client_ingestion
    db_obj.insert(sql_file="sql/client_dim_scd_ingestion.sql")
  File "d:\project\utils\database.py", line 49, in insert
    cursor.executescript(insert_query)
sqlite3.IntegrityError: NOT NULL constraint failed: client_dim.end_date
2023-04-20 23:23:05,471 - utils.database - INFO -> Sending new connection
2023-04-20 23:23:05,536 - __main__ - INFO -> Reading Data file
2023-04-20 23:23:05,555 - __main__ - INFO -> Reading Data file
2023-04-20 23:29:03,162 - __main__ - INFO -> Validations passed
2023-04-20 23:29:31,639 - utils.database - INFO -> SELECT name FROM sqlite_master WHERE type='table' AND name='client_dim'
2023-04-20 23:30:56,395 - utils.database - INFO -> Sending new connection
2023-04-20 23:30:56,452 - __main__ - INFO -> Reading Data file
2023-04-20 23:30:56,470 - __main__ - INFO -> Reading Data file
2023-04-20 23:31:12,315 - __main__ - INFO -> Validations passed
2023-04-20 23:31:14,646 - utils.database - INFO -> SELECT name FROM sqlite_master WHERE type='table' AND name='client_dim'
2023-04-20 23:32:20,504 - __main__ - ERROR -> Failed to ingest data in Orders table!
Traceback (most recent call last):
  File "d:\project\main.py", line 85, in client_ingestion
    db_obj.insert(sql_file="sql/client_dim_scd_ingestion.sql")
  File "d:\project\utils\database.py", line 49, in insert
    cursor.executescript(insert_query)
sqlite3.OperationalError: near ".": syntax error
2023-04-20 23:32:53,790 - utils.database - INFO -> Sending new connection
2023-04-20 23:32:53,842 - __main__ - INFO -> Reading Data file
2023-04-20 23:32:53,861 - __main__ - INFO -> Reading Data file
2023-04-20 23:33:01,757 - __main__ - INFO -> Validations passed
2023-04-20 23:33:04,903 - utils.database - INFO -> SELECT name FROM sqlite_master WHERE type='table' AND name='client_dim'
2023-04-20 23:33:18,920 - __main__ - ERROR -> Failed to ingest data in Orders table!
Traceback (most recent call last):
  File "d:\project\main.py", line 85, in client_ingestion
    db_obj.insert(sql_file="sql/client_dim_scd_ingestion.sql")
  File "d:\project\utils\database.py", line 49, in insert
    cursor.executescript(insert_query)
sqlite3.IntegrityError: NOT NULL constraint failed: client_dim.is_current
2023-04-20 23:35:30,603 - utils.database - INFO -> Sending new connection
2023-04-20 23:35:30,660 - __main__ - INFO -> Reading Data file
2023-04-20 23:35:30,677 - __main__ - INFO -> Reading Data file
2023-04-20 23:35:36,327 - __main__ - INFO -> Validations passed
2023-04-20 23:35:38,521 - utils.database - INFO -> SELECT name FROM sqlite_master WHERE type='table' AND name='client_dim'
2023-04-20 23:38:17,025 - utils.database - INFO -> Sending new connection
2023-04-20 23:38:17,083 - __main__ - INFO -> Reading Data file
2023-04-20 23:38:17,096 - __main__ - INFO -> Reading Data file
2023-04-20 23:38:20,390 - __main__ - INFO -> Validations passed
2023-04-20 23:38:22,526 - utils.database - INFO -> SELECT name FROM sqlite_master WHERE type='table' AND name='client_dim'
2023-04-20 23:38:41,957 - __main__ - INFO -> Reading Data file
2023-04-20 23:38:41,965 - __main__ - INFO -> Reading Data file
2023-04-20 23:38:51,099 - __main__ - INFO -> Validations passed
2023-04-20 23:40:17,444 - utils.database - INFO -> Sending new connection
2023-04-20 23:40:17,498 - __main__ - INFO -> Reading Data file
2023-04-20 23:40:17,515 - __main__ - INFO -> Reading Data file
2023-04-20 23:40:23,210 - __main__ - INFO -> Validations passed
2023-04-20 23:40:25,488 - utils.database - INFO -> SELECT name FROM sqlite_master WHERE type='table' AND name='client_dim'
2023-04-20 23:41:18,999 - __main__ - ERROR -> Failed to ingest data in Orders table!
Traceback (most recent call last):
  File "d:\project\main.py", line 85, in client_ingestion
    db_obj.insert(sql_file="sql/client_dim_scd_ingestion.sql")
  File "d:\project\utils\database.py", line 49, in insert
    cursor.executescript(insert_query)
sqlite3.IntegrityError: NOT NULL constraint failed: client_dim.end_date
2023-04-21 00:38:41,483 - utils.database - INFO -> Sending new connection
2023-04-21 00:38:41,553 - __main__ - INFO -> Reading Data file
2023-04-21 00:38:41,571 - __main__ - INFO -> Reading Data file
2023-04-21 00:41:25,084 - __main__ - INFO -> Validations passed
2023-04-21 00:41:26,880 - utils.database - INFO -> SELECT name FROM sqlite_master WHERE type='table' AND name='client_dim'
2023-04-21 00:41:35,503 - __main__ - INFO -> Reading Data file
2023-04-21 00:41:35,511 - __main__ - INFO -> Reading Data file
2023-04-21 00:41:50,732 - __main__ - INFO -> Validations passed
2023-04-21 00:43:10,561 - utils.database - INFO -> Sending new connection
2023-04-21 00:43:10,612 - __main__ - INFO -> Reading Data file
2023-04-21 00:43:10,626 - __main__ - INFO -> Reading Data file
2023-04-21 00:49:29,018 - __main__ - INFO -> Validations passed
2023-04-21 00:49:31,141 - utils.database - INFO -> SELECT name FROM sqlite_master WHERE type='table' AND name='client_dim'
2023-04-21 00:49:40,495 - __main__ - ERROR -> Failed to ingest data in Orders table!
Traceback (most recent call last):
  File "d:\project\main.py", line 85, in client_ingestion
    db_obj.insert(sql_file="sql/client_dim_scd_ingestion.sql")
  File "d:\project\utils\database.py", line 49, in insert
    cursor.executescript(insert_query)
sqlite3.OperationalError: no such column: tmp_tbl.is_current
2023-04-21 00:50:32,093 - __main__ - INFO -> Reading Data file
2023-04-21 00:50:32,103 - __main__ - INFO -> Reading Data file
2023-04-21 00:50:46,852 - __main__ - INFO -> Validations passed
2023-04-21 00:50:50,492 - utils.database - INFO -> SELECT name FROM sqlite_master WHERE type='table' AND name='client_dim'
2023-04-21 00:51:04,112 - __main__ - ERROR -> Failed to ingest data in Orders table!
Traceback (most recent call last):
  File "d:\project\main.py", line 85, in client_ingestion
    db_obj.insert(sql_file="sql/client_dim_scd_ingestion.sql")
  File "d:\project\utils\database.py", line 49, in insert
    cursor.executescript(insert_query)
sqlite3.OperationalError: no such column: tmp_tbl.is_current
2023-04-21 00:51:52,336 - utils.database - INFO -> Sending new connection
2023-04-21 00:51:52,405 - __main__ - INFO -> Reading Data file
2023-04-21 00:51:52,421 - __main__ - INFO -> Reading Data file
2023-04-21 00:52:02,410 - __main__ - INFO -> Validations passed
2023-04-21 00:52:04,111 - utils.database - INFO -> SELECT name FROM sqlite_master WHERE type='table' AND name='client_dim'
2023-04-21 00:52:10,650 - __main__ - ERROR -> Failed to ingest data in Orders table!
Traceback (most recent call last):
  File "d:\project\main.py", line 85, in client_ingestion
    db_obj.insert(sql_file="sql/client_dim_scd_ingestion.sql")
  File "d:\project\utils\database.py", line 49, in insert
    cursor.executescript(insert_query)
sqlite3.IntegrityError: NOT NULL constraint failed: client_dim.end_date
2023-04-21 00:55:40,347 - utils.database - INFO -> Sending new connection
2023-04-21 00:55:40,403 - __main__ - INFO -> Reading Data file
2023-04-21 00:55:40,419 - __main__ - INFO -> Reading Data file
2023-04-21 00:55:56,568 - __main__ - INFO -> Validations passed
2023-04-21 00:56:16,172 - utils.database - INFO -> SELECT name FROM sqlite_master WHERE type='table' AND name='client_dim'
2023-04-21 00:57:00,554 - __main__ - ERROR -> Failed to ingest data in Orders table!
Traceback (most recent call last):
  File "d:\project\main.py", line 85, in client_ingestion
    db_obj.insert(sql_file="sql/client_dim_scd_ingestion.sql")
  File "d:\project\utils\database.py", line 49, in insert
    cursor.executescript(insert_query)
sqlite3.IntegrityError: NOT NULL constraint failed: client_dim.end_date
2023-04-21 00:57:52,071 - utils.database - INFO -> Sending new connection
2023-04-21 00:57:52,125 - __main__ - INFO -> Reading Data file
2023-04-21 00:57:52,140 - __main__ - INFO -> Reading Data file
2023-04-21 00:58:05,408 - __main__ - INFO -> Validations passed
2023-04-21 00:58:13,196 - utils.database - INFO -> SELECT name FROM sqlite_master WHERE type='table' AND name='client_dim'
2023-04-21 00:58:24,865 - __main__ - ERROR -> Failed to ingest data in Orders table!
Traceback (most recent call last):
  File "d:\project\main.py", line 85, in client_ingestion
    db_obj.insert(sql_file="sql/client_dim_scd_ingestion.sql")
  File "d:\project\utils\database.py", line 49, in insert
    cursor.executescript(insert_query)
sqlite3.IntegrityError: NOT NULL constraint failed: client_dim.end_date
2023-04-21 01:01:41,797 - utils.database - INFO -> Sending new connection
2023-04-21 01:01:41,854 - __main__ - INFO -> Reading Data file
2023-04-21 01:01:41,870 - __main__ - INFO -> Reading Data file
2023-04-21 01:01:46,774 - __main__ - INFO -> Validations passed
2023-04-21 01:01:48,416 - utils.database - INFO -> SELECT name FROM sqlite_master WHERE type='table' AND name='client_dim'
2023-04-21 01:01:51,524 - __main__ - ERROR -> Failed to ingest data in Orders table!
Traceback (most recent call last):
  File "d:\project\main.py", line 85, in client_ingestion
    db_obj.insert(sql_file="sql/client_dim_scd_ingestion.sql")
  File "d:\project\utils\database.py", line 49, in insert
    cursor.executescript(insert_query)
sqlite3.OperationalError: table tmp_tbl already exists
2023-04-21 01:02:10,432 - utils.database - INFO -> Sending new connection
2023-04-21 01:02:10,501 - __main__ - INFO -> Reading Data file
2023-04-21 01:02:10,514 - __main__ - INFO -> Reading Data file
2023-04-21 01:02:15,670 - __main__ - INFO -> Validations passed
2023-04-21 01:02:17,168 - utils.database - INFO -> SELECT name FROM sqlite_master WHERE type='table' AND name='client_dim'
2023-04-21 01:02:20,235 - __main__ - ERROR -> Failed to ingest data in Orders table!
Traceback (most recent call last):
  File "d:\project\main.py", line 85, in client_ingestion
    db_obj.insert(sql_file="sql/client_dim_scd_ingestion.sql")
  File "d:\project\utils\database.py", line 49, in insert
    cursor.executescript(insert_query)
sqlite3.OperationalError: near "OR": syntax error
2023-04-21 08:58:53,380 - utils.database - INFO -> Sending new connection
2023-04-21 08:58:53,611 - __main__ - INFO -> Reading Data file
2023-04-21 08:58:53,734 - __main__ - INFO -> Reading Data file
2023-04-21 08:58:59,564 - __main__ - INFO -> Validations passed
2023-04-21 08:59:05,089 - utils.database - INFO -> SELECT name FROM sqlite_master WHERE type='table' AND name='client_dim'
2023-04-21 08:59:11,609 - __main__ - ERROR -> Failed to ingest data in Orders table!
Traceback (most recent call last):
  File "d:\project\main.py", line 85, in client_ingestion
    db_obj.insert(sql_file="sql/client_dim_scd_ingestion.sql")
  File "d:\project\utils\database.py", line 49, in insert
    cursor.executescript(insert_query)
sqlite3.OperationalError: table tmp_tbl already exists
2023-04-21 09:01:17,741 - utils.database - INFO -> Sending new connection
2023-04-21 09:01:17,886 - __main__ - INFO -> Reading Data file
2023-04-21 09:01:17,926 - __main__ - INFO -> Reading Data file
2023-04-21 09:01:22,670 - __main__ - INFO -> Validations passed
2023-04-21 09:01:24,356 - utils.database - INFO -> SELECT name FROM sqlite_master WHERE type='table' AND name='client_dim'
2023-04-21 09:01:30,937 - __main__ - ERROR -> Failed to ingest data in Orders table!
Traceback (most recent call last):
  File "d:\project\main.py", line 85, in client_ingestion
    db_obj.insert(sql_file="sql/client_dim_scd_ingestion.sql")
  File "d:\project\utils\database.py", line 49, in insert
    cursor.executescript(insert_query)
sqlite3.OperationalError: near "EXIST": syntax error
2023-04-21 09:01:46,865 - utils.database - INFO -> Sending new connection
2023-04-21 09:01:46,955 - __main__ - INFO -> Reading Data file
2023-04-21 09:01:46,986 - __main__ - INFO -> Reading Data file
2023-04-21 09:01:51,155 - __main__ - INFO -> Validations passed
2023-04-21 09:01:52,802 - utils.database - INFO -> SELECT name FROM sqlite_master WHERE type='table' AND name='client_dim'
2023-04-21 09:01:56,131 - __main__ - ERROR -> Failed to ingest data in Orders table!
Traceback (most recent call last):
  File "d:\project\main.py", line 85, in client_ingestion
    db_obj.insert(sql_file="sql/client_dim_scd_ingestion.sql")
  File "d:\project\utils\database.py", line 49, in insert
    cursor.executescript(insert_query)
sqlite3.IntegrityError: NOT NULL constraint failed: client_dim.end_date
2023-04-21 09:06:43,151 - __main__ - INFO -> Reading Data file
2023-04-21 09:06:43,286 - __main__ - INFO -> Reading Data file
2023-04-21 09:06:48,773 - utils.database - INFO -> Sending new connection
2023-04-21 09:06:48,837 - __main__ - INFO -> Reading Data file
2023-04-21 09:06:48,857 - __main__ - INFO -> Reading Data file
2023-04-21 09:06:53,934 - __main__ - INFO -> Validations passed
2023-04-21 09:06:55,519 - utils.database - INFO -> SELECT name FROM sqlite_master WHERE type='table' AND name='client_dim'
2023-04-21 09:07:01,081 - __main__ - ERROR -> Failed to ingest data in Orders table!
Traceback (most recent call last):
  File "d:\project\main.py", line 85, in client_ingestion
    db_obj.insert(sql_file="sql/client_dim_scd_ingestion.sql")
  File "d:\project\utils\database.py", line 49, in insert
    cursor.executescript(insert_query)
sqlite3.IntegrityError: NOT NULL constraint failed: client_dim.is_current
2023-04-21 09:14:56,880 - utils.database - INFO -> Sending new connection
2023-04-21 09:14:56,939 - __main__ - INFO -> Reading Data file
2023-04-21 09:14:56,957 - __main__ - INFO -> Reading Data file
2023-04-21 09:15:00,916 - __main__ - INFO -> Validations passed
2023-04-21 09:15:02,487 - utils.database - INFO -> SELECT name FROM sqlite_master WHERE type='table' AND name='client_dim'
2023-04-21 09:15:06,960 - __main__ - ERROR -> Failed to ingest data in Orders table!
Traceback (most recent call last):
  File "d:\project\main.py", line 85, in client_ingestion
    db_obj.insert(sql_file="sql/client_dim_scd_ingestion.sql")
  File "d:\project\utils\database.py", line 49, in insert
    cursor.executescript(insert_query)
sqlite3.IntegrityError: NOT NULL constraint failed: client_dim.is_current
2023-04-21 09:30:37,182 - utils.database - INFO -> Sending new connection
2023-04-21 09:30:37,239 - __main__ - INFO -> Reading Data file
2023-04-21 09:30:37,258 - __main__ - INFO -> Reading Data file
2023-04-21 09:30:41,333 - __main__ - INFO -> Validations passed
2023-04-21 09:30:41,772 - utils.database - INFO -> SELECT name FROM sqlite_master WHERE type='table' AND name='client_dim'
2023-04-21 09:30:41,834 - __main__ - ERROR -> Failed to ingest data in Orders table!
Traceback (most recent call last):
  File "d:\project\main.py", line 85, in client_ingestion
    db_obj.insert(sql_file="sql/client_dim_scd_ingestion.sql")
  File "d:\project\utils\database.py", line 49, in insert
    cursor.executescript(insert_query)
sqlite3.IntegrityError: NOT NULL constraint failed: client_dim.is_current
2023-04-21 09:38:49,885 - utils.database - INFO -> Sending new connection
2023-04-21 09:38:49,937 - __main__ - INFO -> Reading Data file
2023-04-21 09:38:49,953 - __main__ - INFO -> Reading Data file
2023-04-21 09:38:58,697 - __main__ - INFO -> Validations passed
2023-04-21 09:39:00,237 - utils.database - INFO -> SELECT name FROM sqlite_master WHERE type='table' AND name='client_dim'
2023-04-21 09:39:03,335 - __main__ - ERROR -> Failed to ingest data in Orders table!
Traceback (most recent call last):
  File "d:\project\main.py", line 85, in client_ingestion
    db_obj.insert(sql_file="sql/client_dim_scd_ingestion.sql")
  File "d:\project\utils\database.py", line 49, in insert
    cursor.executescript(insert_query)
sqlite3.OperationalError: near "THEN": syntax error
2023-04-21 09:39:49,727 - utils.database - INFO -> Sending new connection
2023-04-21 09:39:49,780 - __main__ - INFO -> Reading Data file
2023-04-21 09:39:49,796 - __main__ - INFO -> Reading Data file
2023-04-21 09:39:53,321 - __main__ - INFO -> Validations passed
2023-04-21 09:39:55,197 - utils.database - INFO -> SELECT name FROM sqlite_master WHERE type='table' AND name='client_dim'
2023-04-21 09:39:59,599 - __main__ - INFO -> Reading Data file
2023-04-21 09:39:59,612 - __main__ - INFO -> Reading Data file
2023-04-21 09:40:41,831 - __main__ - INFO -> Validations passed
2023-04-21 09:40:44,236 - utils.database - INFO -> SELECT name FROM sqlite_master WHERE type='table' AND name='client_dim'
2023-04-21 09:45:53,781 - utils.database - INFO -> Sending new connection
2023-04-21 09:45:53,846 - __main__ - INFO -> Reading Data file
2023-04-21 09:45:53,861 - __main__ - INFO -> Reading Data file
2023-04-21 09:46:03,198 - __main__ - INFO -> Validations passed
2023-04-21 09:46:06,141 - utils.database - INFO -> SELECT name FROM sqlite_master WHERE type='table' AND name='client_dim'
2023-04-21 09:46:27,868 - __main__ - INFO -> Reading Data file
2023-04-21 09:46:27,884 - __main__ - INFO -> Reading Data file
2023-04-21 09:48:08,258 - utils.database - INFO -> Sending new connection
2023-04-21 09:48:08,325 - __main__ - INFO -> Reading Data file
2023-04-21 09:48:08,343 - __main__ - INFO -> Reading Data file
2023-04-21 09:48:17,126 - __main__ - INFO -> Validations passed
2023-04-21 09:48:18,930 - utils.database - INFO -> SELECT name FROM sqlite_master WHERE type='table' AND name='client_dim'
2023-04-21 09:48:44,411 - __main__ - INFO -> Reading Data file
2023-04-21 09:48:44,426 - __main__ - INFO -> Reading Data file
2023-04-21 09:48:50,109 - __main__ - INFO -> Validations passed
2023-04-21 09:48:51,856 - utils.database - INFO -> SELECT name FROM sqlite_master WHERE type='table' AND name='client_dim'
2023-04-21 11:13:49,642 - utils.database - INFO -> Sending new connection
2023-04-21 11:13:49,750 - __main__ - INFO -> Reading Data file
2023-04-21 11:13:49,779 - __main__ - INFO -> Reading Data file
2023-04-21 11:13:56,838 - __main__ - INFO -> Validations passed
2023-04-21 11:13:58,784 - utils.database - INFO -> SELECT name FROM sqlite_master WHERE type='table' AND name='client_dim'
2023-04-21 11:14:38,176 - __main__ - INFO -> Reading Data file
2023-04-21 11:14:38,216 - __main__ - INFO -> Reading Data file
2023-04-21 13:52:57,344 - utils.database - INFO -> Sending new connection
2023-04-21 13:52:57,400 - __main__ - INFO -> Reading Data file
2023-04-21 13:52:57,420 - __main__ - INFO -> Reading Data file
2023-04-21 13:53:03,196 - __main__ - INFO -> Validations passed
2023-04-21 13:53:05,177 - utils.database - INFO -> SELECT name FROM sqlite_master WHERE type='table' AND name='client_dim'
2023-04-21 13:53:33,399 - __main__ - INFO -> Reading Data file
2023-04-21 13:53:33,408 - __main__ - INFO -> Reading Data file
2023-04-21 13:53:42,417 - __main__ - INFO -> Validations passed
2023-04-21 13:53:44,590 - utils.database - INFO -> SELECT name FROM sqlite_master WHERE type='table' AND name='client_dim'
2023-04-21 13:54:03,926 - __main__ - ERROR -> Failed to ingest data in Orders table!
Traceback (most recent call last):
  File "d:\project\main.py", line 85, in client_ingestion
    db_obj.insert(sql_file="sql/client_dim_scd_ingestion.sql")
  File "d:\project\utils\database.py", line 49, in insert
    cursor.executescript(insert_query)
sqlite3.OperationalError: near ";": syntax error
2023-04-21 13:54:34,611 - utils.database - INFO -> Sending new connection
2023-04-21 13:54:34,673 - __main__ - INFO -> Reading Data file
2023-04-21 13:54:34,686 - __main__ - INFO -> Reading Data file
2023-04-21 13:54:40,309 - __main__ - INFO -> Validations passed
2023-04-21 13:54:44,001 - utils.database - INFO -> SELECT name FROM sqlite_master WHERE type='table' AND name='client_dim'
2023-04-21 13:55:29,356 - __main__ - ERROR -> Failed to ingest data in Orders table!
Traceback (most recent call last):
  File "d:\project\main.py", line 85, in client_ingestion
    db_obj.insert(sql_file="sql/client_dim_scd_ingestion.sql")
  File "d:\project\utils\database.py", line 49, in insert
    cursor.executescript(insert_query)
sqlite3.OperationalError: no such column: targget_tbl.client_name
2023-04-21 13:55:51,186 - utils.database - INFO -> Sending new connection
2023-04-21 13:55:51,244 - __main__ - INFO -> Reading Data file
2023-04-21 13:55:51,262 - __main__ - INFO -> Reading Data file
2023-04-21 13:55:56,586 - __main__ - INFO -> Validations passed
2023-04-21 13:55:57,168 - utils.database - INFO -> SELECT name FROM sqlite_master WHERE type='table' AND name='client_dim'
2023-04-21 14:02:25,164 - utils.database - INFO -> Sending new connection
2023-04-21 14:02:25,224 - __main__ - INFO -> Reading Data file
2023-04-21 14:02:25,241 - __main__ - INFO -> Reading Data file
2023-04-21 14:02:31,383 - __main__ - INFO -> Validations passed
2023-04-21 14:02:33,418 - utils.database - INFO -> SELECT name FROM sqlite_master WHERE type='table' AND name='client_dim'
2023-04-21 14:02:38,470 - __main__ - INFO -> Reading Data file
2023-04-21 14:02:38,487 - __main__ - INFO -> Reading Data file
2023-04-21 14:02:51,881 - __main__ - INFO -> Validations passed
2023-04-21 14:02:57,660 - utils.database - INFO -> SELECT name FROM sqlite_master WHERE type='table' AND name='client_dim'
2023-04-21 14:03:47,521 - utils.database - INFO -> Sending new connection
2023-04-21 14:03:47,586 - __main__ - INFO -> Reading Data file
2023-04-21 14:03:47,604 - __main__ - INFO -> Reading Data file
2023-04-21 14:03:54,902 - __main__ - INFO -> Validations passed
2023-04-21 14:03:56,375 - utils.database - INFO -> SELECT name FROM sqlite_master WHERE type='table' AND name='client_dim'
2023-04-21 14:04:03,170 - __main__ - INFO -> Reading Data file
2023-04-21 14:04:03,184 - __main__ - INFO -> Reading Data file
2023-04-21 14:15:46,685 - utils.database - INFO -> Sending new connection
2023-04-21 14:15:46,754 - __main__ - INFO -> Reading Data file
2023-04-21 14:15:46,772 - __main__ - INFO -> Reading Data file
2023-04-21 14:16:16,685 - utils.database - INFO -> Sending new connection
2023-04-21 14:16:16,742 - __main__ - INFO -> Reading Data file
2023-04-21 14:16:16,759 - __main__ - INFO -> Reading Data file
2023-04-21 14:16:23,231 - __main__ - INFO -> Validations passed
2023-04-21 14:16:24,743 - utils.database - INFO -> SELECT name FROM sqlite_master WHERE type='table' AND name='client_dim'
2023-04-21 14:16:42,987 - __main__ - INFO -> Reading Data file
2023-04-21 14:16:43,002 - __main__ - INFO -> Reading Data file
2023-04-21 14:16:54,116 - __main__ - INFO -> Validations passed
2023-04-21 14:16:55,831 - utils.database - INFO -> SELECT name FROM sqlite_master WHERE type='table' AND name='client_dim'
2023-04-21 14:17:00,915 - __main__ - ERROR -> Failed to ingest data in Orders table!
Traceback (most recent call last):
  File "d:\project\main.py", line 85, in client_ingestion
    db_obj.insert(sql_file="sql/client_dim_scd_ingestion.sql")
  File "d:\project\utils\database.py", line 49, in insert
    cursor.executescript(insert_query)
sqlite3.OperationalError: near ".": syntax error
2023-04-21 14:19:51,570 - utils.database - INFO -> Sending new connection
2023-04-21 14:19:51,626 - __main__ - INFO -> Reading Data file
2023-04-21 14:19:51,645 - __main__ - INFO -> Reading Data file
2023-04-21 14:20:00,883 - __main__ - INFO -> Validations passed
2023-04-21 14:20:02,586 - utils.database - INFO -> SELECT name FROM sqlite_master WHERE type='table' AND name='client_dim'
2023-04-21 14:20:05,780 - __main__ - ERROR -> Failed to ingest data in Orders table!
Traceback (most recent call last):
  File "d:\project\main.py", line 85, in client_ingestion
    db_obj.insert(sql_file="sql/client_dim_scd_ingestion.sql")
  File "d:\project\utils\database.py", line 49, in insert
    cursor.executescript(insert_query)
sqlite3.OperationalError: near ".": syntax error
2023-04-21 14:23:43,862 - utils.database - INFO -> Sending new connection
2023-04-21 14:23:43,920 - __main__ - INFO -> Reading Data file
2023-04-21 14:23:43,939 - __main__ - INFO -> Reading Data file
2023-04-21 14:23:49,913 - __main__ - INFO -> Validations passed
2023-04-21 14:23:51,471 - utils.database - INFO -> SELECT name FROM sqlite_master WHERE type='table' AND name='client_dim'
2023-04-21 15:19:54,123 - utils.database - INFO -> Sending new connection
2023-04-21 15:19:54,180 - __main__ - INFO -> Reading Data file
2023-04-21 15:19:54,199 - __main__ - INFO -> Reading Data file
2023-04-21 15:20:00,221 - __main__ - INFO -> Validations passed
2023-04-21 15:20:01,770 - utils.database - INFO -> SELECT name FROM sqlite_master WHERE type='table' AND name='client_dim'
2023-04-21 15:20:06,378 - __main__ - INFO -> Reading Data file
2023-04-21 15:20:06,389 - __main__ - INFO -> Reading Data file
2023-04-21 15:20:27,397 - __main__ - INFO -> Validations passed
2023-04-21 15:20:30,320 - utils.database - INFO -> SELECT name FROM sqlite_master WHERE type='table' AND name='client_dim'
2023-04-21 15:20:34,365 - __main__ - ERROR -> Failed to ingest data in Orders table!
Traceback (most recent call last):
  File "d:\project\main.py", line 85, in client_ingestion
    db_obj.insert(sql_file="sql/client_dim_scd_ingestion.sql")
  File "d:\project\utils\database.py", line 49, in insert
    cursor.executescript(insert_query)
sqlite3.OperationalError: near "INNER": syntax error
2023-04-21 15:25:32,373 - utils.database - INFO -> Sending new connection
2023-04-21 15:25:32,447 - __main__ - INFO -> Reading Data file
2023-04-21 15:25:32,462 - __main__ - INFO -> Reading Data file
2023-04-21 15:25:37,827 - __main__ - INFO -> Validations passed
2023-04-21 15:25:39,505 - utils.database - INFO -> SELECT name FROM sqlite_master WHERE type='table' AND name='client_dim'
2023-04-21 15:25:42,691 - __main__ - ERROR -> Failed to ingest data in Orders table!
Traceback (most recent call last):
  File "d:\project\main.py", line 85, in client_ingestion
    db_obj.insert(sql_file="sql/client_dim_scd_ingestion.sql")
  File "d:\project\utils\database.py", line 49, in insert
    cursor.executescript(insert_query)
sqlite3.OperationalError: no such table: stage
2023-04-21 15:26:09,027 - utils.database - INFO -> Sending new connection
2023-04-21 15:26:09,085 - __main__ - INFO -> Reading Data file
2023-04-21 15:26:09,104 - __main__ - INFO -> Reading Data file
2023-04-21 15:26:13,910 - __main__ - INFO -> Validations passed
2023-04-21 15:26:15,204 - utils.database - INFO -> SELECT name FROM sqlite_master WHERE type='table' AND name='client_dim'
2023-04-21 15:26:39,865 - __main__ - INFO -> Reading Data file
2023-04-21 15:26:39,878 - __main__ - INFO -> Reading Data file
2023-04-21 15:26:44,916 - __main__ - INFO -> Validations passed
2023-04-21 15:26:46,537 - utils.database - INFO -> SELECT name FROM sqlite_master WHERE type='table' AND name='client_dim'
2023-04-21 15:27:26,512 - utils.database - INFO -> Sending new connection
2023-04-21 15:27:26,577 - __main__ - INFO -> Reading Data file
2023-04-21 15:27:26,594 - __main__ - INFO -> Reading Data file
2023-04-21 15:27:31,172 - __main__ - INFO -> Validations passed
2023-04-21 15:27:31,982 - utils.database - INFO -> SELECT name FROM sqlite_master WHERE type='table' AND name='client_dim'
2023-04-21 15:27:51,653 - __main__ - INFO -> Reading Data file
2023-04-21 15:27:51,665 - __main__ - INFO -> Reading Data file
2023-04-21 15:27:56,176 - __main__ - INFO -> Validations passed
2023-04-21 15:27:56,877 - utils.database - INFO -> SELECT name FROM sqlite_master WHERE type='table' AND name='client_dim'
